Workbook

Sheet Read me
A1: Folio Template Register — consolidated draft
A2: Every template and every message across Folio (Workspace, Document Portal, Correspondence Mailer, governance flows, tools), with nothing exempted: live sends, client-composed e-mails, in-app notices, retired and superseded items, unwired libraries and non-message templates.
A4: Sources
A5: Baseline branch claude/system-remediation-gaps-ahpmsy at commit c33ed52 (2026-10-19 02:41, Release 38).
A6: Live definitions of all 43 adopted flows, read by flow ID on 2026-10-19 at 02:32 UTC (run 08584092297923146268802111059CU06). All 51 catalogue messages match the live flows; every live flow matches its Release 38 package.
A7: config/notification-matrix.config.js (39 required notifications, 7 surplus entries); email-catalogue/catalogue.json; registers/flow-adoption.json (43 adopted, 79 retired).
A8: Brand revalidation 2026-10-19 (baseline d1a8bd0, 21:26 UTC): branding, sub-branding, design system, styling and visual assets rechecked. Column "Brand check (d1a8bd0)" records which repository check, if any, holds each template to the brand; findings B1-B6 are on the Findings sheet; F3, F4 and F7 are corrected there.
A10: Status values
A11: GAP — needs work: outside the catalogue, not brand-reviewed, or a defect.
A12: DECISION — an owner decision is needed before any work.
A13: NOT DEPLOYED — specified, with its own messages, but not in the adopted estate.
A14: INFO — recorded for completeness; no action needed now.
... A23: Draft prepared read-only: nothing in the repository or the tenant was changed.

Sheet Register
A1: ID | B1: Category | C1: Platform | D1: Template or message | E1: Carrier (flow or module) | F1: Flow ID | G1: Step or source | H1: Requirement | I1: Audience | J1: Recipient | K1: Template source | L1: In catalogue | M1: Brand set (2026-10-18) | N1: Brand check (d1a8bd0) | O1: Live state (2026-10-19 02:32) | P1: Status | Q1: Finding or issue | R1: Proposed action | S1: Owner | T1: Target date | U1: Decision / notes
A2: TR-082 | B2: Client e-mail · correspondence | C2: Folio Workspace | D2: official-correspondence — Official Correspondence | E2: core/correspondence-email-service.js → EMAIL (IP_SEND_EMAIL) | F2: df59a69f-92ca-4554-ae68-6b464aa73ef7 | G2: template "official-correspondence" (subject {{referenceId}} — {{subject}}) | H2: RN-021, RN-022 | I2: correspondent (external) | J2: entered by the officer | K2: config/correspondence-email-templates.config.js; docs/reference/correspondence-email-templates/html/official-correspondence.html | L2: No | M2: No | N2: Palette and NITDA alone held by test:brand; type and layout unchecked | O2: Client code; frame live | P2: GAP | Q2: F1: a complete document wrapped again by the IP_SEND_EMAIL frame: "Dear Sir/Madam," plus its own greeting, two headers, labelled "Official correspondence". F4: fails the catalogue checks: no language tag, no preview text, 760 px (limit 640), no presentational tables, no logo, Arial as the main face, box-shadow. Colours are on the palette and the letter carries NITDA alone (test:brand). | R2: Rebuild on the brand set as a fragment; run the catalogue checks on it.
A3: TR-083 | B3: Client e-mail · correspondence | C3: Folio Workspace | D3: request-for-information — Request for Information / Documents | E3: core/correspondence-email-service.js → EMAIL (IP_SEND_EMAIL) | F3: df59a69f-92ca-4554-ae68-6b464aa73ef7 | G3: template "request-for-information" (subject Request for Information — {{referenceId}}) | H3: RN-021, RN-022 | I3: correspondent (external) | J3: entered by the officer | K3: config/correspondence-email-templates.config.js; docs/reference/correspondence-email-templates/html/request-for-information.html | L3: No | M3: No | N3: Palette and NITDA alone held by test:brand; type and layout unchecked | O3: Client code; frame live | P3: GAP | Q3: F1: a complete document wrapped again by the IP_SEND_EMAIL frame: "Dear Sir/Madam," plus its own greeting, two headers, labelled "Official correspondence". F4: fails the catalogue checks: no language tag, no preview text, 760 px (limit 640), no presentational tables, no logo, Arial as the main face, box-shadow. Colours are on the palette and the letter carries NITDA alone (test:brand). | R3: Rebuild on the brand set as a fragment; run the catalogue checks on it.
A4: TR-084 | B4: Client e-mail · correspondence | C4: Folio Workspace | D4: document-transmittal — Document Transmittal | E4: core/correspondence-email-service.js → EMAIL (IP_SEND_EMAIL) | F4: df59a69f-92ca-4554-ae68-6b464aa73ef7 | G4: template "document-transmittal" (subject Transmittal — {{referenceId}} — {{subject}}) | H4: RN-021, RN-022 | I4: correspondent (external) | J4: entered by the officer | K4: config/correspondence-email-templates.config.js; docs/reference/correspondence-email-templates/html/document-transmittal.html | L4: No | M4: No | N4: Palette and NITDA alone held by test:brand; type and layout unchecked | O4: Client code; frame live | P4: GAP | Q4: F1: a complete document wrapped again by the IP_SEND_EMAIL frame: "Dear Sir/Madam," plus its own greeting, two headers, labelled "Official correspondence". F4: fails the catalogue checks: no language tag, no preview text, 760 px (limit 640), no presentational tables, no logo, Arial as the main face, box-shadow. Colours are on the palette and the letter carries NITDA alone (test:brand). | R4: Rebuild on the brand set as a fragment; run the catalogue checks on it.
A5: TR-085 | B5: Client e-mail · correspondence | C5: Folio Workspace | D5: meeting-invitation — Meeting / Engagement Invitation | E5: core/correspondence-email-service.js → EMAIL (IP_SEND_EMAIL) | F5: df59a69f-92ca-4554-ae68-6b464aa73ef7 | G5: template "meeting-invitation" (subject Invitation — {{subject}} — {{referenceId}}) | H5: RN-021, RN-022 | I5: correspondent (external) | J5: entered by the officer | K5: config/correspondence-email-templates.config.js; docs/reference/correspondence-email-templates/html/meeting-invitation.html | L5: No | M5: No | N5: Palette and NITDA alone held by test:brand; type and layout unchecked | O5: Client code; frame live | P5: GAP | Q5: F1: a complete document wrapped again by the IP_SEND_EMAIL frame: "Dear Sir/Madam," plus its own greeting, two headers, labelled "Official correspondence". F4: fails the catalogue checks: no language tag, no preview text, 760 px (limit 640), no presentational tables, no logo, Arial as the main face, box-shadow. Colours are on the palette and the letter carries NITDA alone (test:brand). | R5: Rebuild on the brand set as a fragment; run the catalogue checks on it.
A6: TR-086 | B6: Client e-mail · correspondence | C6: Folio Workspace | D6: circular-notice — Circular / General Notice | E6: core/correspondence-email-service.js → EMAIL (IP_SEND_EMAIL) | F6: df59a69f-92ca-4554-ae68-6b464aa73ef7 | G6: template "circular-notice" (subject Circular / Notice — {{subject}}) | H6: RN-021, RN-022 | I6: correspondent (external) | J6: entered by the officer | K6: config/correspondence-email-templates.config.js; docs/reference/correspondence-email-templates/html/circular-notice.html | L6: No | M6: No | N6: Palette and NITDA alone held by test:brand; type and layout unchecked | O6: Client code; frame live | P6: GAP | Q6: F1: a complete document wrapped again by the IP_SEND_EMAIL frame: "Dear Sir/Madam," plus its own greeting, two headers, labelled "Official correspondence". F4: fails the catalogue checks: no language tag, no preview text, 760 px (limit 640), no presentational tables, no logo, Arial as the main face, box-shadow. Colours are on the palette and the letter carries NITDA alone (test:brand). | R6: Rebuild on the brand set as a fragment; run the catalogue checks on it.
A7: TR-087 | B7: Client e-mail · correspondence | C7: Folio Workspace | D7: closure-response — Closure / Final Response | E7: core/correspondence-email-service.js → EMAIL (IP_SEND_EMAIL) | F7: df59a69f-92ca-4554-ae68-6b464aa73ef7 | G7: template "closure-response" (subject Final Response — {{referenceId}}) | H7: RN-021, RN-022 | I7: correspondent (external) | J7: entered by the officer | K7: config/correspondence-email-templates.config.js; docs/reference/correspondence-email-templates/html/closure-response.html | L7: No | M7: No | N7: Palette and NITDA alone held by test:brand; type and layout unchecked | O7: Client code; frame live | P7: GAP | Q7: F1: a complete document wrapped again by the IP_SEND_EMAIL frame: "Dear Sir/Madam," plus its own greeting, two headers, labelled "Official correspondence". F4: fails the catalogue checks: no language tag, no preview text, 760 px (limit 640), no presentational tables, no logo, Arial as the main face, box-shadow. Colours are on the palette and the letter carries NITDA alone (test:brand). | R7: Rebuild on the brand set as a fragment; run the catalogue checks on it.
A8: TR-089 | B8: Client e-mail · report | C8: Folio Workspace | D8: Management report email | E8: modules/reports.js → EMAIL (IP_SEND_EMAIL) | F8: df59a69f-92ca-4554-ae68-6b464aa73ef7 | G8: modules/reports.js (reportHtml) | H8: RN-024 | I8: originator / chosen recipients | K8: inline in modules/reports.js | L8: No | M8: No | N8: Not covered by any brand check | O8: Client code; frame live | P8: GAP | Q8: F1: a complete document wrapped again by the IP_SEND_EMAIL frame: "Dear Sir/Madam," plus its own greeting, two headers, labelled "Official correspondence". F4: no template; a bare <h1> page built in code, with no inline styling: its tables rely on Workspace CSS classes that do not travel with the e-mail. | R8: Give it a template and send a fragment.
A9: TR-090 | B9: Client e-mail · report | C9: Folio Workspace | D9: Statistics report email | E9: modules/statistics.js → EMAIL (IP_SEND_EMAIL) | F9: df59a69f-92ca-4554-ae68-6b464aa73ef7 | G9: modules/statistics.js (htmlDoc) | H9: RN-024 | I9: originator / chosen recipients | K9: inline in modules/statistics.js | L9: No | M9: No | N9: Not covered by any brand check | O9: Client code; frame live | P9: GAP | Q9: F1: a complete document wrapped again by the IP_SEND_EMAIL frame: "Dear Sir/Madam," plus its own greeting, two headers, labelled "Official correspondence". F4: no template; a bare <h1> page built in code, with no inline styling: its tables rely on Workspace CSS classes that do not travel with the e-mail. | R9: Give it a template and send a fragment.
A10: TR-074 | B10: Client e-mail · staff notice | C10: Folio Workspace | D10: ack-reminder — Reminder: please acknowledge {{referenceId}} — {{title}} | E10: core/staff-notice-service.js → EMAIL (IP_SEND_EMAIL) | F10: df59a69f-92ca-4554-ae68-6b464aa73ef7 | G10: StaffNoticeTemplates["RN-012"] | H10: RN-012 | I10: assignee | J10: resolved from the record (registry hold until StaffNoticeDelivery.recipients = staff) | K10: config/staff-notice-templates.config.js | L10: No | M10: No (text header, no logo, no DGO mark) | N10: Palette held by tests/staff-notice.test.mjs; layout and logo unchecked | O10: Client code; frame live | P10: GAP | Q10: F1: a complete document wrapped again by the IP_SEND_EMAIL frame: "Dear Sir/Madam," plus its own greeting, two headers, labelled "Official correspondence". F4: outside the owner's brand set; on the palette (tests/staff-notice.test.mjs), but no logo and no DGO mark on internal mail. | R10: Render a body fragment for the frame; add to the brand review.
A11: TR-075 | B11: Client e-mail · staff notice | C11: Folio Workspace | D11: owner-notice — FastTrack notice: {{referenceId}} — {{title}} | E11: core/staff-notice-service.js → EMAIL (IP_SEND_EMAIL) | F11: df59a69f-92ca-4554-ae68-6b464aa73ef7 | G11: StaffNoticeTemplates["RN-015"] | H11: RN-015 | I11: owner | J11: resolved from the record (registry hold until StaffNoticeDelivery.recipients = staff) | K11: config/staff-notice-templates.config.js | L11: No | M11: No (text header, no logo, no DGO mark) | N11: Palette held by tests/staff-notice.test.mjs; layout and logo unchecked | O11: Client code; frame live | P11: GAP | Q11: F1: a complete document wrapped again by the IP_SEND_EMAIL frame: "Dear Sir/Madam," plus its own greeting, two headers, labelled "Official correspondence". F4: outside the owner's brand set; on the palette (tests/staff-notice.test.mjs), but no logo and no DGO mark on internal mail. | R11: Render a body fragment for the frame; add to the brand review.
A12: TR-076 | B12: Client e-mail · staff notice | C12: Folio Workspace | D12: approval-request — Approval requested: {{referenceId}} — {{title}} | E12: core/staff-notice-service.js → EMAIL (IP_SEND_EMAIL) | F12: df59a69f-92ca-4554-ae68-6b464aa73ef7 | G12: StaffNoticeTemplates["RN-017"] | H12: RN-017 | I12: approver | J12: resolved from the record (registry hold until StaffNoticeDelivery.recipients = staff) | K12: config/staff-notice-templates.config.js | L12: No | M12: No (text header, no logo, no DGO mark) | N12: Palette held by tests/staff-notice.test.mjs; layout and logo unchecked | O12: Client code; frame live | P12: GAP | Q12: F1: a complete document wrapped again by the IP_SEND_EMAIL frame: "Dear Sir/Madam," plus its own greeting, two headers, labelled "Official correspondence". F4: outside the owner's brand set; on the palette (tests/staff-notice.test.mjs), but no logo and no DGO mark on internal mail. | R12: Render a body fragment for the frame; add to the brand review.
A13: TR-077 | B13: Client e-mail · staff notice | C13: Folio Workspace | D13: approval-decision — Decision on {{referenceId}}: {{decision}} | E13: core/staff-notice-service.js → EMAIL (IP_SEND_EMAIL) | F13: df59a69f-92ca-4554-ae68-6b464aa73ef7 | G13: StaffNoticeTemplates["RN-018"] | H13: RN-018 | I13: originator | J13: resolved from the record (registry hold until StaffNoticeDelivery.recipients = staff) | K13: config/staff-notice-templates.config.js | L13: No | M13: No (text header, no logo, no DGO mark) | N13: Palette held by tests/staff-notice.test.mjs; layout and logo unchecked | O13: Client code; frame live | P13: GAP | Q13: F1: a complete document wrapped again by the IP_SEND_EMAIL frame: "Dear Sir/Madam," plus its own greeting, two headers, labelled "Official correspondence". F4: outside the owner's brand set; on the palette (tests/staff-notice.test.mjs), but no logo and no DGO mark on internal mail. | R13: Render a body fragment for the frame; add to the brand review.
A14: TR-078 | B14: Client e-mail · staff notice | C14: Folio Workspace | D14: reassignment — Reassigned to you: {{referenceId}} — {{title}} | E14: core/staff-notice-service.js → EMAIL (IP_SEND_EMAIL) | F14: df59a69f-92ca-4554-ae68-6b464aa73ef7 | G14: StaffNoticeTemplates["RN-019"] | H14: RN-019 | I14: assignee | J14: resolved from the record (registry hold until StaffNoticeDelivery.recipients = staff) | K14: config/staff-notice-templates.config.js | L14: No | M14: No (text header, no logo, no DGO mark) | N14: Palette held by tests/staff-notice.test.mjs; layout and logo unchecked | O14: Client code; frame live | P14: GAP | Q14: F1: a complete document wrapped again by the IP_SEND_EMAIL frame: "Dear Sir/Madam," plus its own greeting, two headers, labelled "Official correspondence". F4: outside the owner's brand set; on the palette (tests/staff-notice.test.mjs), but no logo and no DGO mark on internal mail. | R14: Render a body fragment for the frame; add to the brand review.
A15: TR-079 | B15: Client e-mail · staff notice | C15: Folio Workspace | D15: comment — New comment on {{referenceId}} — {{title}} | E15: core/staff-notice-service.js → EMAIL (IP_SEND_EMAIL) | F15: df59a69f-92ca-4554-ae68-6b464aa73ef7 | G15: StaffNoticeTemplates["RN-020"] | H15: RN-020 | I15: assignee | J15: resolved from the record (registry hold until StaffNoticeDelivery.recipients = staff) | K15: config/staff-notice-templates.config.js | L15: No | M15: No (text header, no logo, no DGO mark) | N15: Palette held by tests/staff-notice.test.mjs; layout and logo unchecked | O15: Client code; frame live | P15: GAP | Q15: F1: a complete document wrapped again by the IP_SEND_EMAIL frame: "Dear Sir/Madam," plus its own greeting, two headers, labelled "Official correspondence". F4: outside the owner's brand set; on the palette (tests/staff-notice.test.mjs), but no logo and no DGO mark on internal mail. | R15: Render a body fragment for the frame; add to the brand review.
A16: TR-080 | B16: Client e-mail · staff notice | C16: Folio Workspace | D16: escalation — Escalated (level {{level}}): {{referenceId}} — {{title}} | E16: core/staff-notice-service.js → EMAIL (IP_SEND_EMAIL) | F16: df59a69f-92ca-4554-ae68-6b464aa73ef7 | G16: StaffNoticeTemplates["RN-034"] | H16: RN-034 | I16: owner | J16: resolved from the record (registry hold until StaffNoticeDelivery.recipients = staff) | K16: config/staff-notice-templates.config.js | L16: No | M16: No (text header, no logo, no DGO mark) | N16: Palette held by tests/staff-notice.test.mjs; layout and logo unchecked | O16: Client code; frame live | P16: GAP | Q16: F1: a complete document wrapped again by the IP_SEND_EMAIL frame: "Dear Sir/Madam," plus its own greeting, two headers, labelled "Official correspondence". F4: outside the owner's brand set; on the palette (tests/staff-notice.test.mjs), but no logo and no DGO mark on internal mail. | R16: Render a body fragment for the frame; add to the brand review.
A17: TR-081 | B17: Client e-mail · staff notice | C17: Folio Workspace | D17: delegation — Delegated to you: {{referenceId}} — {{title}} | E17: core/staff-notice-service.js → EMAIL (IP_SEND_EMAIL) | F17: df59a69f-92ca-4554-ae68-6b464aa73ef7 | G17: StaffNoticeTemplates["RN-036"] | H17: RN-036 | I17: assignee | J17: resolved from the record (registry hold until StaffNoticeDelivery.recipients = staff) | K17: config/staff-notice-templates.config.js | L17: No | M17: No (text header, no logo, no DGO mark) | N17: Palette held by tests/staff-notice.test.mjs; layout and logo unchecked | O17: Client code; frame live | P17: GAP | Q17: F1: a complete document wrapped again by the IP_SEND_EMAIL frame: "Dear Sir/Madam," plus its own greeting, two headers, labelled "Official correspondence". F4: outside the owner's brand set; on the palette (tests/staff-notice.test.mjs), but no logo and no DGO mark on internal mail. | R17: Render a body fragment for the frame; add to the brand review.
A18: TR-040 | B18: Flow e-mail · catalogue | C18: Folio Workspace | D18: EMAIL.email-with-attachments — email-with-attachments | E18: IP_SEND_EMAIL | F18: df59a69f-92ca-4554-ae68-6b464aa73ef7 | G18: Send_Email_With_Attachments | H18: RN-021, RN-022, RN-024 | J18: @outputs('Compose_SendEmail_Recipients') | K18: email-catalogue/shared/email-with-attachments.html | L18: Yes | M18: Yes | N18: Palette, alt text, width and image host checked (test:emailcatalogue, test:brand; ACCEPTANCE 51/51) | O18: Live, identical to template | P18: GAP | Q18: F1: since release 36 this frame wraps the client bodies (staff notices, Correspondence Desk letters, reports, statistics), which are complete documents: two greetings, two headers, nested pages, all labelled "Official correspondence". | R18: Send body fragments from the Workspace (no flow release), or make the frame pass a complete document through.
A19: TR-041 | B19: Flow e-mail · catalogue | C19: Folio Workspace | D19: EMAIL.email — email | E19: IP_SEND_EMAIL | F19: df59a69f-92ca-4554-ae68-6b464aa73ef7 | G19: Send_Email | H19: RN-012, 015, 017, 018, 019, 020, 021, 022, 024, 034, 036 | J19: @outputs('Compose_SendEmail_Recipients') | K19: email-catalogue/shared/email-with-attachments.html | L19: Yes | M19: Yes | N19: Palette, alt text, width and image host checked (test:emailcatalogue, test:brand; ACCEPTANCE 51/51) | O19: Live, identical to template | P19: GAP | Q19: F1: since release 36 this frame wraps the client bodies (staff notices, Correspondence Desk letters, reports, statistics), which are complete documents: two greetings, two headers, nested pages, all labelled "Official correspondence". | R19: Send body fragments from the Workspace (no flow release), or make the frame pass a complete document through.
A20: TR-052 | B20: Flow e-mail · no catalogue template | C20: Folio Workspace | D20: Flow run telemetry | E20: BULK_OPS_DATA_RETRIEVAL_HTTP | F20: 5aab9e61-ab9f-4af1-9f2b-eaba23a1bf06 | G20: Send_Telemetry_Email | H20: operational | J20: dgsRegistry@nitda.gov.ng | K20: inline in the flow definition | L20: No | M20: No | O20: Live | P20: GAP | Q20: A 249-character telemetry mail outside the package scope, to a fixed address; not in the catalogue. | R20: Remove it, or bring it into the package and catalogue.
A21: TR-055 | B21: Flow e-mail · no catalogue template | C21: Governance (Estate Console) | D21: Run report (final status) to the registry | E21: 01 - GOV - Provision HTTP Flow Registry | F21: 17a85efb-1ed2-45c9-a602-2ad6f8bb7ead | G21: Send_Final_Report_Email | H21: RN-028, SN-006 | J21: @concat('dgsregistry@nitda.gov.ng',if(or(empty(trim(string(coalesce(triggerOutputs()?['hea | K21: inline in the flow definition | L21: No | M21: No | N21: Not covered by any brand check; captured body uses off-palette colours (#004578 and others) and Segoe UI | O21: Live, unchanged since 2026-10-01 capture | P21: GAP | Q21: F3: Outside the catalogue: not generated from a template, not brand-reviewed. Bare document: no language tag, preview text or logo. | R21: Bring under the catalogue (a flow package or a template file), or record why not.
A22: TR-056 | B22: Flow e-mail · no catalogue template | C22: Governance (Estate Console) | D22: Run report (final status) to the registry | E22: 02 - GOV - Register HTTP Flow Truth | F22: 651ae389-eeed-4bf0-9799-67bd964ebe71 | G22: Send_Final_Report_Email | H22: SN-006 | J22: dgsRegistry@nitda.gov.ng | K22: inline in the flow definition | L22: No | M22: No | N22: Not covered by any brand check; captured body uses off-palette colours (#004578 and others) and Segoe UI | O22: Live, unchanged since 2026-10-01 capture | P22: GAP | Q22: F3: Outside the catalogue: not generated from a template, not brand-reviewed. Bare document: no language tag, preview text or logo. | R22: Bring under the catalogue (a flow package or a template file), or record why not.
A23: TR-057 | B23: Flow e-mail · no catalogue template | C23: Governance (Estate Console) | D23: Run report (final status) to the registry | E23: 03 - GOV - Record HTTP Flow Execution | F23: 0545e19a-c34a-45db-bd11-27b87a34973e | G23: Send_Final_Report_Email | H23: SN-006 | J23: dgsRegistry@nitda.gov.ng | K23: inline in the flow definition | L23: No | M23: No | N23: Not covered by any brand check; captured body uses off-palette colours (#004578 and others) and Segoe UI | O23: Live, unchanged since 2026-10-01 capture | P23: GAP | Q23: F3: Outside the catalogue: not generated from a template, not brand-reviewed. Bare document: no language tag, preview text or logo. | R23: Bring under the catalogue (a flow package or a template file), or record why not.
A24: TR-058 | B24: Flow e-mail · no catalogue template | C24: Governance (Estate Console) | D24: Stale flow alert to technical owner | E24: 04 - GOV - Audit HTTP Flow Registry | F24: 3e9e1342-5027-4c0f-bdd3-1e06aa7f2a3b | G24: Send_Stale_Owner_And_Governance_Alert | H24: SN-006 | J24: @coalesce(item()?['TechnicalOwnerEmail'],'dgsRegistry@nitda.gov.ng') | K24: inline in the flow definition | L24: No | M24: No | N24: Not covered by any brand check; captured body uses off-palette colours (#004578 and others) and Segoe UI | O24: Live, unchanged since 2026-10-01 capture | P24: GAP | Q24: F3: Outside the catalogue: not generated from a template, not brand-reviewed. Logo loads from nitda.gov.ng/assets/, not the Portal host the owner set on 2026-10-18. | R24: Bring under the catalogue (a flow package or a template file), or record why not.
A25: TR-059 | B25: Flow e-mail · no catalogue template | C25: Governance (Estate Console) | D25: Stale flow reminder or escalation | E25: 04 - GOV - Audit HTTP Flow Registry | F25: 3e9e1342-5027-4c0f-bdd3-1e06aa7f2a3b | G25: Send_Stale_Reminder_Or_Escalation | H25: SN-006 | J25: @coalesce(item()?['TechnicalOwnerEmail'],'dgsRegistry@nitda.gov.ng') | K25: inline in the flow definition | L25: No | M25: No | N25: Not covered by any brand check; captured body uses off-palette colours (#004578 and others) and Segoe UI | O25: Live, unchanged since 2026-10-01 capture | P25: GAP | Q25: F3: Outside the catalogue: not generated from a template, not brand-reviewed. Logo loads from nitda.gov.ng/assets/, not the Portal host the owner set on 2026-10-18. | R25: Bring under the catalogue (a flow package or a template file), or record why not.
A26: TR-060 | B26: Flow e-mail · no catalogue template | C26: Governance (Estate Console) | D26: Failing flow alert to technical owner | E26: 04 - GOV - Audit HTTP Flow Registry | F26: 3e9e1342-5027-4c0f-bdd3-1e06aa7f2a3b | G26: Send_Failure_Owner_And_Governance_Alert | H26: SN-006 | J26: @coalesce(item()?['TechnicalOwnerEmail'],'dgsRegistry@nitda.gov.ng') | K26: inline in the flow definition | L26: No | M26: No | N26: Not covered by any brand check; captured body uses off-palette colours (#004578 and others) and Segoe UI | O26: Live, unchanged since 2026-10-01 capture | P26: GAP | Q26: F3: Outside the catalogue: not generated from a template, not brand-reviewed. Logo loads from nitda.gov.ng/assets/, not the Portal host the owner set on 2026-10-18. | R26: Bring under the catalogue (a flow package or a template file), or record why not.
A27: TR-061 | B27: Flow e-mail · no catalogue template | C27: Governance (Estate Console) | D27: Failing flow reminder or escalation | E27: 04 - GOV - Audit HTTP Flow Registry | F27: 3e9e1342-5027-4c0f-bdd3-1e06aa7f2a3b | G27: Send_Failure_Reminder_Or_Escalation | H27: SN-006 | J27: @coalesce(item()?['TechnicalOwnerEmail'],'dgsRegistry@nitda.gov.ng') | K27: inline in the flow definition | L27: No | M27: No | N27: Not covered by any brand check; captured body uses off-palette colours (#004578 and others) and Segoe UI | O27: Live, unchanged since 2026-10-01 capture | P27: GAP | Q27: F3: Outside the catalogue: not generated from a template, not brand-reviewed. Logo loads from nitda.gov.ng/assets/, not the Portal host the owner set on 2026-10-18. | R27: Bring under the catalogue (a flow package or a template file), or record why not.
A28: TR-062 | B28: Flow e-mail · no catalogue template | C28: Governance (Estate Console) | D28: Flow recovered ([CLEARED]) | E28: 04 - GOV - Audit HTTP Flow Registry | F28: 3e9e1342-5027-4c0f-bdd3-1e06aa7f2a3b | G28: Send_Recovery_Notification | H28: SN-006 | J28: @coalesce(first(body('Get_Recovery_Registry_Record')?['value'])?['TechnicalOwnerEmail'],it | K28: inline in the flow definition | L28: No | M28: No | N28: Not covered by any brand check; captured body uses off-palette colours (#004578 and others) and Segoe UI | O28: Live, unchanged since 2026-10-01 capture | P28: GAP | Q28: F3: Outside the catalogue: not generated from a template, not brand-reviewed. Logo loads from nitda.gov.ng/assets/, not the Portal host the owner set on 2026-10-18. | R28: Bring under the catalogue (a flow package or a template file), or record why not.
A29: TR-063 | B29: Flow e-mail · no catalogue template | C29: Governance (Estate Console) | D29: Run report (final status) to the registry | E29: 04 - GOV - Audit HTTP Flow Registry | F29: 3e9e1342-5027-4c0f-bdd3-1e06aa7f2a3b | G29: Send_Final_Report_Email | H29: SN-006 | J29: dgsRegistry@nitda.gov.ng | K29: inline in the flow definition | L29: No | M29: No | N29: Not covered by any brand check; captured body uses off-palette colours (#004578 and others) and Segoe UI | O29: Live, unchanged since 2026-10-01 capture | P29: GAP | Q29: F3: Outside the catalogue: not generated from a template, not brand-reviewed. Bare document: no language tag, preview text or logo. | R29: Bring under the catalogue (a flow package or a template file), or record why not.
A30: TR-064 | B30: Flow e-mail · no catalogue template | C30: Governance (Estate Console) | D30: Execution report to the registry | E30: 05 - GOV - Retire HTTP Flow | F30: 493b4ab7-8f63-4fab-8121-746c2cac7f98 | G30: Send_Execution_Report_Email | H30: SN-006 | J30: dgsRegistry@nitda.gov.ng | K30: inline in the flow definition | L30: No | M30: No | N30: Not covered by any brand check; captured body uses off-palette colours (#004578 and others) and Segoe UI | O30: Live, unchanged since 2026-10-01 capture | P30: GAP | Q30: F3: Outside the catalogue: not generated from a template, not brand-reviewed. Bare document: no language tag, preview text or logo. | R30: Bring under the catalogue (a flow package or a template file), or record why not.
A31: TR-065 | B31: Flow e-mail · no catalogue template | C31: Governance (Estate Console) | D31: Run report (final status) to the registry | E31: 05 - GOV - Retire HTTP Flow | F31: 493b4ab7-8f63-4fab-8121-746c2cac7f98 | G31: Send_Final_Report_Email | H31: SN-006 | J31: dgsRegistry@nitda.gov.ng | K31: inline in the flow definition | L31: No | M31: No | N31: Not covered by any brand check; captured body uses off-palette colours (#004578 and others) and Segoe UI | O31: Live, unchanged since 2026-10-01 capture | P31: GAP | Q31: F3: Outside the catalogue: not generated from a template, not brand-reviewed. Bare document: no language tag, preview text or logo. | R31: Bring under the catalogue (a flow package or a template file), or record why not.
A32: TR-066 | B32: Flow e-mail · no catalogue template | C32: Governance (Estate Console) | D32: Registry exception to its assignee | E32: 06 - GOV - Registry Exception Notification | F32: 87a74d7e-7435-4e34-baa1-7e759ebf5565 | G32: Send_Exception_Email | H32: RN-039 | J32: @if(or(empty(trim(string(item()?['AssignedToEmail']))),equals(toLower(trim(string(item()?[ | K32: inline in the flow definition | L32: No | M32: No | N32: Not covered by any brand check; captured body uses off-palette colours (#004578 and others) and Segoe UI | O32: Live, unchanged since 2026-10-01 capture | P32: GAP | Q32: F3: Outside the catalogue: not generated from a template, not brand-reviewed. Bare document: no language tag, preview text or logo. | R32: Bring under the catalogue (a flow package or a template file), or record why not.
... A36: TR-070 | B36: Flow e-mail · no catalogue template | C36: Governance (Estate Console) | D36: Run report (final status) to the registry | E36: 08 - GOV - Discover and Register HTTP Consumers | F36: f5e7679f-ca1b-4216-8a6e-bb6c044ed06f | G36: Send_Final_Report_Email | H36: SN-006 | J36: dgsRegistry@nitda.gov.ng | K36: inline in the flow definition | L36: No | M36: No | N36: Not covered by any brand check; captured body uses off-palette colours (#004578 and others) and Segoe UI | O36: Live, unchanged since 2026-10-01 capture | P36: GAP | Q36: F3: Outside the catalogue: not generated from a template, not brand-reviewed. Bare document: no language tag, preview text or logo. | R36: Bring under the catalogue (a flow package or a template file), or record why not.
A37: TR-071 | B37: Flow e-mail · no catalogue template | C37: Correspondence Mailer | D37: Mailer sign-in code | E37: DGO_MAIL_AUTH | F37: 7d90f8f0-fa91-4aed-899c-b2bce5b70694 | G37: Send_Code | H37: operational | J37: @outputs('Compose_Challenge')?['email'] | K37: inline in the flow definition | L37: No | M37: No | O37: Live, unchanged since 2026-10-01 capture | P37: GAP | Q37: F4: Outside the catalogue: not generated from a template, not brand-reviewed. Bare three-paragraph body; the code is in the subject line. | R37: Bring under the catalogue (a flow package or a template file), or record why not.
A38: TR-107 | B38: Implied, not sent | C38: Folio Workspace | D38: Internal support request ("Ask the support team") | E38: core/support-service.js → SUBSIDIARY_ACTIONS (CREATESUPPORTREQUEST) | F38: 31c0aaf0-ddbb-478c-9a98-bc013265c4c7 | H38: none (supportEmail dgs@nitda.gov.ng in config/support-routing.config.js) | K38: none (old library IP-10) | L38: No | P38: GAP | Q38: F5: the flow has no case for CREATESUPPORTREQUEST, so no mail reaches dgs@nitda.gov.ng. | R38: Decide: implement the route and a template, or remove the panel.
A39: TR-091 | B39: Mailer letter | C39: Correspondence Mailer | D39: cover-letter — Official letter — cover email (letter attached) | E39: DGO_MAIL_SEND | F39: 0fb53e16-fa57-41a9-9880-752c3a4d4749 | G39: mailer/js/seed-templates.js | H39: Mailer correspondence | I39: correspondent (external) | K39: mailer/js/seed-templates.js | L39: No | M39: No | N39: Not covered by any brand check | O39: Mailer client; send flow live | P39: GAP | Q39: F4: starter letter outside the catalogue and every brand check: set in Cambria serif with #1B1B1B, neither a brand face nor a palette value. | R39: Review against the brand set.
A40: TR-092 | B40: Mailer letter | C40: Correspondence Mailer | D40: invitation — Invitation — meeting, workshop or engagement | E40: DGO_MAIL_SEND | F40: 0fb53e16-fa57-41a9-9880-752c3a4d4749 | G40: mailer/js/seed-templates.js | H40: Mailer correspondence | I40: correspondent (external) | K40: mailer/js/seed-templates.js | L40: No | M40: No | N40: Not covered by any brand check | O40: Mailer client; send flow live | P40: GAP | Q40: F4: starter letter outside the catalogue and every brand check: set in Cambria serif with #1B1B1B, neither a brand face nor a palette value. | R40: Review against the brand set.
A41: TR-093 | B41: Mailer letter | C41: Correspondence Mailer | D41: follow-up — Follow-up — reminder on an earlier letter | E41: DGO_MAIL_SEND | F41: 0fb53e16-fa57-41a9-9880-752c3a4d4749 | G41: mailer/js/seed-templates.js | H41: Mailer correspondence | I41: correspondent (external) | K41: mailer/js/seed-templates.js | L41: No | M41: No | N41: Not covered by any brand check | O41: Mailer client; send flow live | P41: GAP | Q41: F4: starter letter outside the catalogue and every brand check: set in Cambria serif with #1B1B1B, neither a brand face nor a palette value. | R41: Review against the brand set.
A42: TR-094 | B42: Mailer letter | C42: Correspondence Mailer | D42: Letterhead variant — Official Correspondence | E42: DGO_MAIL_SEND | F42: 0fb53e16-fa57-41a9-9880-752c3a4d4749 | G42: mailer/js/letterhead.js (letterhead.generated.js) | H42: Mailer correspondence | I42: correspondent (external) | K42: compiled from config/correspondence-email-templates.config.js | L42: No | M42: No | N42: NITDA alone held by test:brand (letterhead.js); colours from the checked config | O42: Mailer client; send flow live | P42: GAP | Q42: F4: byte-identical to the Correspondence Desk letter, with its structural shortfalls (no double frame: DGO_MAIL_SEND passes it through). | R42: Fixed with the Correspondence Desk rebuild.
A43: TR-095 | B43: Mailer letter | C43: Correspondence Mailer | D43: Letterhead variant — Request for Information / Documents | E43: DGO_MAIL_SEND | F43: 0fb53e16-fa57-41a9-9880-752c3a4d4749 | G43: mailer/js/letterhead.js (letterhead.generated.js) | H43: Mailer correspondence | I43: correspondent (external) | K43: compiled from config/correspondence-email-templates.config.js | L43: No | M43: No | N43: NITDA alone held by test:brand (letterhead.js); colours from the checked config | O43: Mailer client; send flow live | P43: GAP | Q43: F4: byte-identical to the Correspondence Desk letter, with its structural shortfalls (no double frame: DGO_MAIL_SEND passes it through). | R43: Fixed with the Correspondence Desk rebuild.
...

Sheet Summary
A1: Rows by category and status (formulas over the Register sheet)
A3: Category | B3: GAP | C3: DECISION | D3: NOT DEPLOYED | E3: INFO | F3: OK | G3: RETIRED | H3: WITHDRAWN | I3: Total | J3: No owner yet
A4: Client e-mail · correspondence | B4: =COUNTIFS(Register!$B$2:$B$269,$A4,Register!$P$2:$P$269,B$3) | C4: =COUNTIFS(Register!$B$2:$B$269,$A4,Register!$P$2:$P$269,C$3) | D4: =COUNTIFS(Register!$B$2:$B$269,$A4,Register!$P$2:$P$269,D$3) | E4: =COUNTIFS(Register!$B$2:$B$269,$A4,Register!$P$2:$P$269,E$3) | F4: =COUNTIFS(Register!$B$2:$B$269,$A4,Register!$P$2:$P$269,F$3) | G4: =COUNTIFS(Register!$B$2:$B$269,$A4,Register!$P$2:$P$269,G$3) | H4: =COUNTIFS(Register!$B$2:$B$269,$A4,Register!$P$2:$P$269,H$3) | I4: =SUM(B4:H4) | J4: =COUNTIFS(Register!$B$2:$B$269,$A4,Register!$S$2:$S$269,"")
A5: Client e-mail · report | B5: =COUNTIFS(Register!$B$2:$B$269,$A5,Register!$P$2:$P$269,B$3) | C5: =COUNTIFS(Register!$B$2:$B$269,$A5,Register!$P$2:$P$269,C$3) | D5: =COUNTIFS(Register!$B$2:$B$269,$A5,Register!$P$2:$P$269,D$3) | E5: =COUNTIFS(Register!$B$2:$B$269,$A5,Register!$P$2:$P$269,E$3) | F5: =COUNTIFS(Register!$B$2:$B$269,$A5,Register!$P$2:$P$269,F$3) | G5: =COUNTIFS(Register!$B$2:$B$269,$A5,Register!$P$2:$P$269,G$3) | H5: =COUNTIFS(Register!$B$2:$B$269,$A5,Register!$P$2:$P$269,H$3) | I5: =SUM(B5:H5) | J5: =COUNTIFS(Register!$B$2:$B$269,$A5,Register!$S$2:$S$269,"")
A6: Client e-mail · staff notice | B6: =COUNTIFS(Register!$B$2:$B$269,$A6,Register!$P$2:$P$269,B$3) | C6: =COUNTIFS(Register!$B$2:$B$269,$A6,Register!$P$2:$P$269,C$3) | D6: =COUNTIFS(Register!$B$2:$B$269,$A6,Register!$P$2:$P$269,D$3) | E6: =COUNTIFS(Register!$B$2:$B$269,$A6,Register!$P$2:$P$269,E$3) | F6: =COUNTIFS(Register!$B$2:$B$269,$A6,Register!$P$2:$P$269,F$3) | G6: =COUNTIFS(Register!$B$2:$B$269,$A6,Register!$P$2:$P$269,G$3) | H6: =COUNTIFS(Register!$B$2:$B$269,$A6,Register!$P$2:$P$269,H$3) | I6: =SUM(B6:H6) | J6: =COUNTIFS(Register!$B$2:$B$269,$A6,Register!$S$2:$S$269,"")
A7: Flow e-mail · catalogue | B7: =COUNTIFS(Register!$B$2:$B$269,$A7,Register!$P$2:$P$269,B$3) | C7: =COUNTIFS(Register!$B$2:$B$269,$A7,Register!$P$2:$P$269,C$3) | D7: =COUNTIFS(Register!$B$2:$B$269,$A7,Register!$P$2:$P$269,D$3) | E7: =COUNTIFS(Register!$B$2:$B$269,$A7,Register!$P$2:$P$269,E$3) | F7: =COUNTIFS(Register!$B$2:$B$269,$A7,Register!$P$2:$P$269,F$3) | G7: =COUNTIFS(Register!$B$2:$B$269,$A7,Register!$P$2:$P$269,G$3) | H7: =COUNTIFS(Register!$B$2:$B$269,$A7,Register!$P$2:$P$269,H$3) | I7: =SUM(B7:H7) | J7: =COUNTIFS(Register!$B$2:$B$269,$A7,Register!$S$2:$S$269,"")
A8: Flow e-mail · no catalogue template | B8: =COUNTIFS(Register!$B$2:$B$269,$A8,Register!$P$2:$P$269,B$3) | C8: =COUNTIFS(Register!$B$2:$B$269,$A8,Register!$P$2:$P$269,C$3) | D8: =COUNTIFS(Register!$B$2:$B$269,$A8,Register!$P$2:$P$269,D$3) | E8: =COUNTIFS(Register!$B$2:$B$269,$A8,Register!$P$2:$P$269,E$3) | F8: =COUNTIFS(Register!$B$2:$B$269,$A8,Register!$P$2:$P$269,F$3) | G8: =COUNTIFS(Register!$B$2:$B$269,$A8,Register!$P$2:$P$269,G$3) | H8: =COUNTIFS(Register!$B$2:$B$269,$A8,Register!$P$2:$P$269,H$3) | I8: =SUM(B8:H8) | J8: =COUNTIFS(Register!$B$2:$B$269,$A8,Register!$S$2:$S$269,"")
A9: Flow · sends no e-mail | B9: =COUNTIFS(Register!$B$2:$B$269,$A9,Register!$P$2:$P$269,B$3) | C9: =COUNTIFS(Register!$B$2:$B$269,$A9,Register!$P$2:$P$269,C$3) | D9: =COUNTIFS(Register!$B$2:$B$269,$A9,Register!$P$2:$P$269,D$3) | E9: =COUNTIFS(Register!$B$2:$B$269,$A9,Register!$P$2:$P$269,E$3) | F9: =COUNTIFS(Register!$B$2:$B$269,$A9,Register!$P$2:$P$269,F$3) | G9: =COUNTIFS(Register!$B$2:$B$269,$A9,Register!$P$2:$P$269,G$3) | H9: =COUNTIFS(Register!$B$2:$B$269,$A9,Register!$P$2:$P$269,H$3) | I9: =SUM(B9:H9) | J9: =COUNTIFS(Register!$B$2:$B$269,$A9,Register!$S$2:$S$269,"")
A10: Implied, not sent | B10: =COUNTIFS(Register!$B$2:$B$269,$A10,Register!$P$2:$P$269,B$3) | C10: =COUNTIFS(Register!$B$2:$B$269,$A10,Register!$P$2:$P$269,C$3) | D10: =COUNTIFS(Register!$B$2:$B$269,$A10,Register!$P$2:$P$269,D$3) | E10: =COUNTIFS(Register!$B$2:$B$269,$A10,Register!$P$2:$P$269,E$3) | F10: =COUNTIFS(Register!$B$2:$B$269,$A10,Register!$P$2:$P$269,F$3) | G10: =COUNTIFS(Register!$B$2:$B$269,$A10,Register!$P$2:$P$269,G$3) | H10: =COUNTIFS(Register!$B$2:$B$269,$A10,Register!$P$2:$P$269,H$3) | I10: =SUM(B10:H10) | J10: =COUNTIFS(Register!$B$2:$B$269,$A10,Register!$S$2:$S$269,"")
A11: In-app notice | B11: =COUNTIFS(Register!$B$2:$B$269,$A11,Register!$P$2:$P$269,B$3) | C11: =COUNTIFS(Register!$B$2:$B$269,$A11,Register!$P$2:$P$269,C$3) | D11: =COUNTIFS(Register!$B$2:$B$269,$A11,Register!$P$2:$P$269,D$3) | E11: =COUNTIFS(Register!$B$2:$B$269,$A11,Register!$P$2:$P$269,E$3) | F11: =COUNTIFS(Register!$B$2:$B$269,$A11,Register!$P$2:$P$269,F$3) | G11: =COUNTIFS(Register!$B$2:$B$269,$A11,Register!$P$2:$P$269,G$3) | H11: =COUNTIFS(Register!$B$2:$B$269,$A11,Register!$P$2:$P$269,H$3) | I11: =SUM(B11:H11) | J11: =COUNTIFS(Register!$B$2:$B$269,$A11,Register!$S$2:$S$269,"")
A12: Mailer letter | B12: =COUNTIFS(Register!$B$2:$B$269,$A12,Register!$P$2:$P$269,B$3) | C12: =COUNTIFS(Register!$B$2:$B$269,$A12,Register!$P$2:$P$269,C$3) | D12: =COUNTIFS(Register!$B$2:$B$269,$A12,Register!$P$2:$P$269,D$3) | E12: =COUNTIFS(Register!$B$2:$B$269,$A12,Register!$P$2:$P$269,E$3) | F12: =COUNTIFS(Register!$B$2:$B$269,$A12,Register!$P$2:$P$269,F$3) | G12: =COUNTIFS(Register!$B$2:$B$269,$A12,Register!$P$2:$P$269,G$3) | H12: =COUNTIFS(Register!$B$2:$B$269,$A12,Register!$P$2:$P$269,H$3) | I12: =SUM(B12:H12) | J12: =COUNTIFS(Register!$B$2:$B$269,$A12,Register!$S$2:$S$269,"")
A13: Old library (unwired) | B13: =COUNTIFS(Register!$B$2:$B$269,$A13,Register!$P$2:$P$269,B$3) | C13: =COUNTIFS(Register!$B$2:$B$269,$A13,Register!$P$2:$P$269,C$3) | D13: =COUNTIFS(Register!$B$2:$B$269,$A13,Register!$P$2:$P$269,D$3) | E13: =COUNTIFS(Register!$B$2:$B$269,$A13,Register!$P$2:$P$269,E$3) | F13: =COUNTIFS(Register!$B$2:$B$269,$A13,Register!$P$2:$P$269,F$3) | G13: =COUNTIFS(Register!$B$2:$B$269,$A13,Register!$P$2:$P$269,G$3) | H13: =COUNTIFS(Register!$B$2:$B$269,$A13,Register!$P$2:$P$269,H$3) | I13: =SUM(B13:H13) | J13: =COUNTIFS(Register!$B$2:$B$269,$A13,Register!$S$2:$S$269,"")
A14: One-off set-up report | B14: =COUNTIFS(Register!$B$2:$B$269,$A14,Register!$P$2:$P$269,B$3) | C14: =COUNTIFS(Register!$B$2:$B$269,$A14,Register!$P$2:$P$269,C$3) | D14: =COUNTIFS(Register!$B$2:$B$269,$A14,Register!$P$2:$P$269,D$3) | E14: =COUNTIFS(Register!$B$2:$B$269,$A14,Register!$P$2:$P$269,E$3) | F14: =COUNTIFS(Register!$B$2:$B$269,$A14,Register!$P$2:$P$269,F$3) | G14: =COUNTIFS(Register!$B$2:$B$269,$A14,Register!$P$2:$P$269,G$3) | H14: =COUNTIFS(Register!$B$2:$B$269,$A14,Register!$P$2:$P$269,H$3) | I14: =SUM(B14:H14) | J14: =COUNTIFS(Register!$B$2:$B$269,$A14,Register!$S$2:$S$269,"")
A15: Other template · Config template | B15: =COUNTIFS(Register!$B$2:$B$269,$A15,Register!$P$2:$P$269,B$3) | C15: =COUNTIFS(Register!$B$2:$B$269,$A15,Register!$P$2:$P$269,C$3) | D15: =COUNTIFS(Register!$B$2:$B$269,$A15,Register!$P$2:$P$269,D$3) | E15: =COUNTIFS(Register!$B$2:$B$269,$A15,Register!$P$2:$P$269,E$3) | F15: =COUNTIFS(Register!$B$2:$B$269,$A15,Register!$P$2:$P$269,F$3) | G15: =COUNTIFS(Register!$B$2:$B$269,$A15,Register!$P$2:$P$269,G$3) | H15: =COUNTIFS(Register!$B$2:$B$269,$A15,Register!$P$2:$P$269,H$3) | I15: =SUM(B15:H15) | J15: =COUNTIFS(Register!$B$2:$B$269,$A15,Register!$S$2:$S$269,"")
... A26: Surplus send (matrix) | B26: =COUNTIFS(Register!$B$2:$B$269,$A26,Register!$P$2:$P$269,B$3) | C26: =COUNTIFS(Register!$B$2:$B$269,$A26,Register!$P$2:$P$269,C$3) | D26: =COUNTIFS(Register!$B$2:$B$269,$A26,Register!$P$2:$P$269,D$3) | E26: =COUNTIFS(Register!$B$2:$B$269,$A26,Register!$P$2:$P$269,E$3) | F26: =COUNTIFS(Register!$B$2:$B$269,$A26,Register!$P$2:$P$269,F$3) | G26: =COUNTIFS(Register!$B$2:$B$269,$A26,Register!$P$2:$P$269,G$3) | H26: =COUNTIFS(Register!$B$2:$B$269,$A26,Register!$P$2:$P$269,H$3) | I26: =SUM(B26:H26) | J26: =COUNTIFS(Register!$B$2:$B$269,$A26,Register!$S$2:$S$269,"")
A27: Total | B27: =SUM(B4:B26) | C27: =SUM(C4:C26) | D27: =SUM(D4:D26) | E27: =SUM(E4:E26) | F27: =SUM(F4:F26) | G27: =SUM(G4:G26) | H27: =SUM(H4:H26) | I27: =SUM(I4:I26) | J27: =SUM(J4:J26)
A29: Check: rows on the Register | B29: =COUNTA(Register!$A$2:$A$269)

Sheet Findings
A1: Finding | B1: Statement | C1: Register rows citing it
A2: F1 | B2: Release 36 frames every e-mail sent through IP_SEND_EMAIL a second time: staff notices (8), Correspondence Desk letters (RN-021, RN-022) and report e-mails (RN-024) arrive with two greetings, two headers and a nested page, labelled "Official correspondence". Confirmed live 2026-10-19. | C2: =COUNTIF(Register!$Q$2:$Q$269,"*F1:*")
A3: F2 | B3: Required notifications with no template: none remain. RN-020 and RN-022 (built 2026-10-19 00:07) and RN-025 and RN-035 (Release 38) now have carriers; RN-020 and RN-022 inherit F1. | C3: n/a (resolved)
A4: F3 | B4: The governance flows send 16 mails from 9 inline bodies outside the catalogue; 11 have no logo or structure; GOV-04 loads its logo from nitda.gov.ng/assets/, not the catalogue image host (folio-portal.page.gd/email-assets/ since release 39, 2026-10-19; correspondence-gateway.rf.gd is suspended). The captured bodies use off-palette colours (#004578 and others) and Segoe UI; no brand check covers them. | C4: =COUNTIF(Register!$Q$2:$Q$269,"*F3:*")
A5: F4 | B5: Corrected 2026-10-19. Client templates are outside the catalogue and the owner's 2026-10-18 brand set. Staff notices are held to the palette by tests/staff-notice.test.mjs; Correspondence Desk letters and the Mailer letterhead are held to the palette and to NITDA alone by test:brand. Not covered by any check: report e-mails (no inline styling), the Mailer starter letters (Cambria serif, #1B1B1B) and the sign-in code mail; nor the type and layout of the Desk letters (Arial, 760 px, no lang, no preheader, no logo). | C5: =COUNTIF(Register!$Q$2:$Q$269,"*F4:*")
A6: F5 | B6: Implied but unsent: the Workspace support request (no flow case) and a citizen notice when acknowledgement is overdue. | C6: =COUNTIF(Register!$Q$2:$Q$269,"*F5:*")
A7: F6 | B7: Specified flows not yet in the estate carry their own inline templates (user directory sync, endpoint inventory, Flow Estate live report). | C7: =COUNTIF(Register!$Q$2:$Q$269,"*F6:*")
A8: F7 | B8: Qualified 2026-10-19. The older 20-template library still sits beside the catalogue, unwired. ITEM-68 (which carried the 2026-10-03 one-source decision) is RESOLVED, so this is recorded, not reopened; the brand README still describes these 20 as the live e-mails (B1). | C8: =COUNTIF(Register!$Q$2:$Q$269,"*F7:*")
A9: B1 | B9: styles/dgo-design-system/README.md describes an older state: PENDING empty and 59 outputs (test:brand: 2 pending, 115 classified); e-mail row "20 notification templates, 6 correspondence templates" and RX-01 "12 internal staff emails (as text)" describe the unwired library, not the 51-message catalogue; Packaged and Embedded lists (3, 16) shorter than the gate (6, 17). | C9: n/a (no template row)
A10: B2 | B10: Sub-brand applied unevenly in internal e-mail: the owner resolution (email-catalogue/ACCEPTANCE.md, 2026-10-18) puts the DGO Digital Ops logo on internal mail; 27 catalogue messages carry it, 8 internal ones do not (status DECISION), 6 of which sign as "Folio · NITDA Digital Correspondence", a name in neither the brand README nor PLATFORM_NAMING.md. Staff notices carry no DGO mark either. | C10: =COUNTIF(Register!$Q$2:$Q$269,"*B2:*")
A11: B3 | B11: tests/brand-authority.test.mjs still lists the New E-Scan template as PENDING (off-brand), but it now uses only palette colours and the brand image host; it can be classified EMAIL (a test change, no flow release). | C11: n/a (no template row)
A12: B4 | B12: The Portal logos (document-portal/ds/logo/) are earlier exports, not byte-identical to the masters; the brand README itself says replace them at the next Portal review. | C12: n/a (no template row)
A13: B5 | B13: Unreferenced legacy HTML steps in released packages load images from third-party hosts: Single_Task_Assignment (3) and BULK_OPS_DATA_RETRIEVAL_HTTP (2) a NITDA logo on d15k2d11r6t6rl.cloudfront.net; the scan flow (5) also flaticon.com, myfiles.space and the placeholder yourcdn.com. None feeds a send; cleanup can ride a later release. | C13: n/a (no template row)
A14: B6 | B14: Not covered by any brand check: GOV mail bodies, Mailer starter letters, report e-mails, and the type and layout of the Desk letters. | C14: n/a (no template row)
