Workbook

Sheet Cover
A1: NITDA Folio — Endpoint and Flow Register and Report
A2: Register workbook. The report of the same reference presents these registers with the findings and the action plan.
A4: Document control
A5: Document reference | B5: NITDA-FOLIO-EFR-001
A6: Version | B6: 1.0
A7: Date | B7: 2026-09-28
A8: Status | B8: Issued for action
A9: Baseline branch | B9: claude/system-remediation-gaps-ahpmsy
A10: Baseline commit | B10: 72f2deb
A11: Scope | B11: The six Folio platforms and every endpoint, flow, list and service they require. Nothing outside the baseline branch was read.
A13: Contents
A14: Summary | B14: Live counts by status, severity and priority
A15: Platforms | B15: R1 · The six platforms
A16: Endpoints | B16: R2 · Endpoint register: every endpoint and route the platforms require
A17: Operations | B17: R3 · Operation register: operations sent to shared flows
A18: Supporting | B18: R4 · Supporting flows, lists and services
A19: Mail | B19: R5 · Mail obligations register (39 rows from the notification matrix)
A20: Findings | B20: R6 · Findings register
A21: Actions | B21: R7 · Action register: prioritised, with owner, acceptance test and tracking columns
A22: Excluded | B22: R8 · Declared but not required
A23: Sources | B23: R9 · Sources and evidence
A25: Legend
A26: Provided | B26: An exported flow does what the caller sends.
A27: Provided with caveat | B27: It works, with a limit the platform depends on.
A28: Gap | B28: The platform sends something the flow does not handle, or the key is answered by the wrong flow.
A29: Not examined | B29: The live flow or service is not held in the branch, so it was not examined.
A30: Yellow cells | B30: Tracking columns to fill in (finding status, action status, assignee, target date). Everything else is evidence and should not be edited.
A32: How “provided” is judged
A33: Four records: the register (wired workflow), the owner map of 24 Sep (intended flow), the branch live reading of 27 Sep (flow answering each key) and the flow definitions in the branch. The definitions are exports matched by name, so they can differ from what runs (crosswalk verified: 0). No live calls were made for this register.

Sheet Summary
A1: Summary
A2: Counts are formulas over the registers and update when statuses change.
A4: Endpoint register by status
A5: Value | B5: Count
A6: Provided | B6: =COUNTIF(Endpoints!$J$5:$J$40,A6)
A7: Provided with caveat | B7: =COUNTIF(Endpoints!$J$5:$J$40,A7)
A8: Gap | B8: =COUNTIF(Endpoints!$J$5:$J$40,A8)
A9: Not examined | B9: =COUNTIF(Endpoints!$J$5:$J$40,A9)
A10: Total | B10: =SUM(B6:B9)
A12: Endpoint register by platform
A13: Value | B13: Count
A14: Folio Workspace | B14: =COUNTIF(Endpoints!$B$5:$B$40,A14)
A15: NITDA Document Portal | B15: =COUNTIF(Endpoints!$B$5:$B$40,A15)
A16: DGO Correspondence Mailer | B16: =COUNTIF(Endpoints!$B$5:$B$40,A16)
A17: Folio Flow Workbench | B17: =COUNTIF(Endpoints!$B$5:$B$40,A17)
A18: Folio Vault | B18: =COUNTIF(Endpoints!$B$5:$B$40,A18)
A19: Folio Estate Console and Admin Suite | B19: =COUNTIF(Endpoints!$B$5:$B$40,A19)
A20: Total | B20: =SUM(B14:B19)
A22: Supporting register by status
A23: Value | B23: Count
A24: Provided | B24: =COUNTIF(Supporting!$F$5:$F$14,A24)
A25: Provided with caveat | B25: =COUNTIF(Supporting!$F$5:$F$14,A25)
A26: Gap | B26: =COUNTIF(Supporting!$F$5:$F$14,A26)
A27: Not examined | B27: =COUNTIF(Supporting!$F$5:$F$14,A27)
A28: Total | B28: =SUM(B24:B27)
A30: Findings by severity
A31: Value | B31: Count
A32: Critical | B32: =COUNTIF(Findings!$B$5:$B$16,A32)
A33: High | B33: =COUNTIF(Findings!$B$5:$B$16,A33)
A34: Medium | B34: =COUNTIF(Findings!$B$5:$B$16,A34)
A35: Low | B35: =COUNTIF(Findings!$B$5:$B$16,A35)
A36: Total | B36: =SUM(B32:B35)
A38: Findings by status
A39: Value | B39: Count
A40: Open | B40: =COUNTIF(Findings!$H$5:$H$16,A40)
A41: In progress | B41: =COUNTIF(Findings!$H$5:$H$16,A41)
A42: Closed | B42: =COUNTIF(Findings!$H$5:$H$16,A42)
A43: Accepted | B43: =COUNTIF(Findings!$H$5:$H$16,A43)
A44: Total | B44: =SUM(B40:B43)
A46: Actions by priority
...

Sheet Platforms
A1: R1 · Platforms
A2: The six runnable platforms of NITDA Folio, from scripts/platforms.config.mjs.
A4: ID | B4: Code | C4: Name | D4: Port | E4: Network use
A5: P-01 | B5: runtime | C5: Folio Workspace | D5: 8080 | E5: 16 flow URLs: 15 JSON POST and 1 raw PUT (SCAN_INTAKE)
A6: P-02 | B6: portal | C6: NITDA Document Portal | D6: 8081 | E6: 7 flow URLs
A7: P-03 | B7: console | C7: Folio Estate Console | D7: 8082 | E7: Probes the Workspace keys. No endpoints of its own.
A8: P-04 | B8: mailer | C8: DGO Correspondence Mailer | D8: 8083 | E8: 7 flow URLs of its own. Standalone: shares no key with the Workspace.
A9: P-05 | B9: workbench | C9: Folio Flow Workbench | D9: 8765 | E9: 2 relay routes, plus direct calls to a flow URL
A10: P-06 | B10: capsule | C10: Folio Vault | D10: 8787 | E10: 8 admin routes and a health probe. Optional.

Sheet Endpoints
A1: R2 · Endpoint register
A2: Every endpoint or route a platform calls. Status: Provided, Provided with caveat, Gap, Not examined. Live flow is from the 27 Sep reading; intended flow is from the owner map.
A4: ID | B4: Platform | C4: Key or route | D4: Transport | E4: Action or operation | F4: Required by (call site) | G4: Live flow (27 Sep) | H4: Intended flow (owner map) | I4: Evidence examined | J4: Status | K4: Findings | L4: Actions | M4: Note
A5: EP-W01 | B5: Folio Workspace | C5: FETCH_ALL | D5: POST JSON | E5: fetchAll | F5: core/data-loader.js:54 (boot and every reload) | G5: IP_FETCH_ALL_BOOTSTRAP | H5: IP_FETCH_ALL__EXTENDED_ENDPOINT (migration) | I5: IP_FETCH_ALL_BOOTSTRAP 17 and 24 Sep; IP_FETCH_ALL__EXTENDED 11 Sep | J5: Provided with caveat | K5: F-08 | L5: A-11 | M5: Each list read is capped at 500 rows (200 for departments). emails and approvals are always empty.
A6: EP-W02 | B6: Folio Workspace | C6: FETCH_ACTIVITIES | D6: POST JSON | E6: LIST-ACTIVITIES | F6: core/data-loader.js:54 (fallback); modules/lookup.js:57; modules/fasttrack.js:33 | G6: IP_Get_Docs_Endpoint | H6: No row in the owner map | I6: IP_Get_Docs_Endpoint 12 and 17 Sep | J6: Provided | M6: Directory-gated; returns filtered documents. Shares its flow with GET_DOCS.
A7: EP-W03 | B7: Folio Workspace | C7: GET_DOCS | D7: POST JSON | E7: getDocs | F7: modules/lookup.js:57; modules/fasttrack.js:33 | G7: IP_Get_Docs_Endpoint | H7: IP_Get_Docs_Endpoint | I7: IP_Get_Docs_Endpoint 12 and 17 Sep | J7: Provided
A8: EP-W04 | B8: Folio Workspace | C8: REFERENCE_DATA | D8: POST JSON | E8: lookups | F8: modules/fasttrack.js:33 | G8: IP_Reference_Data_Endpoint | H8: IP_Reference_Data_Endpoint | I8: IP_Reference_Data_Endpoint 18 Sep | J8: Provided | M8: Users, categories, departments.
A9: EP-W05 | B9: Folio Workspace | C9: SUBSIDIARY_ACTIONS | D9: POST JSON | E9: INIT; route carried in payload | F9: core/acknowledgement-service.js:171 (ACKNOWLEDGE); core/offline-action-queue.js:14; core/support-service.js:8 (CREATESUPPORTREQUEST); modules/lookup.js:57; modules/fasttrack.js:33 | G9: IP_Dynamic_Global_Actions_Endpoint | H9: IP_Subsidiary_Actions_Endpoint | I9: IP_Subsidiary_Actions_Endpoint 5 Sep: telemetry and CORS only | J9: Gap | K9: F-01 | L9: A-04 | M9: The live flow handles none of the routes the Workspace sends. Readiness register ITEM-65 is blocked on this.
A10: EP-W06 | B10: Folio Workspace | C10: DYNAMIC_ACTIONS | D10: POST JSON | E10: dynamicGlobalAction | F10: See operation register OP-D01 to OP-D09 | G10: IP_Dynamic_Global_Actions_Endpoint | H10: IP_Dynamic_Global_Actions_Endpoint | I10: IP_Dynamic_Global_Actions_Endpoint 17 Sep: 4 cases | J10: Gap | K10: F-02 | L10: A-05, A-06 | M10: Implements 4 of the 19 operations in its known list. The Workspace also sends operations outside the list.
A11: EP-W07 | B11: Folio Workspace | C11: EMAIL | D11: POST JSON | E11: dispatchEmail | F11: core/correspondence-email-service.js:70; modules/statistics.js:48; modules/reports.js:50 | G11: IP_SEND_EMAIL | H11: IP_SEND_EMAIL | I11: IP_SEND_EMAIL 5 Sep: recipients composed from the payload | J11: Provided with caveat | K11: F-06 | L11: A-09 | M11: Notification-matrix rows RN-021 and RN-024 still describe the older fixed-address sender.
A12: EP-W08 | B12: Folio Workspace | C12: FETCH_EMAIL_ATTACHMENTS | D12: POST JSON | E12: fetchEmailAttachments | F12: modules/activities.js:132 | G12: IP_Retrieve_Email_Attachment_Endpoint | H12: IP_Retrieve_Email_Attachment_Endpoint | I12: IP_Retrieve_Email_Attachment_Endpoint 6 Sep | J12: Provided with caveat | K12: F-11 | L12: A-22 | M12: No caller check; reads Outlook directly.
A13: EP-W09 | B13: Folio Workspace | C13: SINGLE_ASSIGNMENT | D13: POST JSON (flat) | E13: singleassignment | F13: modules/single-assignment.js:140 | G13: Single_Task_Assignment | H13: IP_Single_Assignment_Endpoint (migration) | I13: No export of the live flow. Intended package IP_Single_Assignment_Endpoint.READY assigns and audits, sends no mail. | J13: Not examined | K13: F-07 | L13: A-10 | M13: Live flow is an older one with no export in the branch.
A14: EP-W10 | B14: Folio Workspace | C14: BULK_ASSIGNMENT | D14: POST JSON | E14: bulkassignment | F14: modules/bulk-assignment.js:19 | G14: BULK OPS DATA RETRIEVAL HTTP | H14: IP_Bulk_Assignment_Endpoint | I14: BULKOPSDATARETRIEVALHTTP 11 Sep reads documents; IP_Bulk_Assignment_Endpoint 1 Sep assigns | J14: Gap | K14: F-03 | L14: A-07 | M14: Confirmed live: a document-retrieval flow answers this key.
A15: EP-W11 | B15: Folio Workspace | C15: EMAIL_RELATED_TASK | D15: POST JSON | E15: emailtotaskassignment | F15: modules/lookup.js:152 | G15: IP_Create_Email_Assignment | H15: IP_Create_Email_Assignment_Endpoint (migration) | I15: IP_Create_Email_Assignment 11 Sep; IP_Create_Email_Assignment_Endpoint 6 Sep | J15: Provided with caveat | K15: F-07, F-11 | L15: A-10, A-22 | M15: Six mail actions go to one named address. No caller check.
A16: EP-W12 | B16: Folio Workspace | C16: AI_DOC_ANALYSIS | D16: POST JSON | E16: aiAnalyseEventDocs (operation classify) | F16: modules/correspondence.js:128; modules/executive.js:30 | G16: AI_Document_Processing | H16: AI_Document_Processing | I16: AI_Document_Processing 11 Sep, flow id 901eb9d7. Live flow id fefa43c6 is not held. | J16: Gap | K16: F-04, F-05 | L16: A-08, A-01 | M16: The export ignores action, messages, operation and referenceId.
A17: EP-W13 | B17: Folio Workspace | C17: AI_CHAT | D17: POST JSON | E17: aiChat | F17: modules/assistant.js:48 | G17: AI_Document_Processing | H17: AI_Document_Processing | I17: As EP-W12 | J17: Gap | K17: F-04, F-05 | L17: A-08, A-01 | M17: Shares its flow with EP-W12.
A18: EP-W14 | B18: Folio Workspace | C18: OTP_GENERATE | D18: POST JSON (flat) | E18: generate (operation requestOtp) | F18: core/otp-service.js:6; core/otp-identity.js:95 only if auth is enabled | G18: IP_OTP_VERIFY | H18: IP_OTP_Endpoint (repoint pending) | I18: IP_OTP_VERIFY 5 Sep switches on action and handles generate | J18: Provided with caveat | K18: F-09 | L18: A-12 | M18: Auth is disabled, so the sign-in use is dormant.
A19: EP-W15 | B19: Folio Workspace | C19: OTP_VERIFY | D19: POST JSON (flat) | E19: verify (operation verifyOtp) | F19: core/otp-service.js:7; core/otp-identity.js:124 only if auth is enabled | G19: IP_OTP_VERIFY | H19: IP_OTP_VERIFY | I19: IP_OTP_VERIFY 5 Sep | J19: Provided
A20: EP-W16 | B20: Folio Workspace | C20: SCAN_INTAKE | D20: PUT raw bytes | E20: none | F20: core/scan-intake-service.js | G20: IP_SCAN_INTAKE | H20: IP_SCAN_INTAKE_Endpoint_v2.1 (migration) | I20: IP_SCAN_INTAKE 4 Sep; v2.1 13 Sep | J20: Provided | M20: Headers X-DGO-Filename, X-DGO-Sha256, X-DGO-Size. Live trigger is not tenant-authenticated (ITEM-59). No contract entry; must not go through DataClient.request().
A21: EP-P01 | B21: NITDA Document Portal | C21: SUBMISSION | D21: POST JSON | E21: record; +verification | F21: document-portal/js/core.js:333 | G21: CG_Submission_Endpoint | H21: CG_Submission_Endpoint | I21: npm run keyimpl: implemented | J21: Provided | M21: Pilot-critical. Returns {referenceId, uploads[]}; 403 verification_required.
A22: EP-P02 | B22: NITDA Document Portal | C22: UPLOAD | D22: PUT raw file | E22: X-Upload-Ticket header | F22: core.js:371 | G22: CG_Upload_Endpoint | H22: CG_Upload_Endpoint | I22: npm run keyimpl: implemented | J22: Provided | M22: Pilot-critical. Returns {stored, attachmentLink}.
A23: EP-P03 | B23: NITDA Document Portal | C23: SUPPORT | D23: POST JSON | E23: create case | F23: core.js:388 | G23: CG_Portal_Support_Endpoint | H23: CG_Portal_Support_Endpoint | I23: npm run keyimpl: implemented | J23: Provided | M23: Returns {caseRef}. Failures queued for retry.
A24: EP-P04 | B24: NITDA Document Portal | C24: VERIFY | D24: POST JSON | E24: {email} | F24: core.js:418 | G24: CG_Portal_Verification_Endpoint | H24: CG_Verification_Endpoint | I24: npm run keyimpl: implemented | J24: Provided | M24: Returns {sent, expiresAt}; 429. Live and owner-map names differ.
A25: EP-P05 | B25: NITDA Document Portal | C25: VERIFY_CONFIRM | D25: POST JSON | E25: {email, code} | F25: core.js:435 | G25: CG_Portal_Verification_Confirmation_Endpoint | H25: CG_Portal_Verification_Confirmation_Endpoint | I25: npm run keyimpl: implemented | J25: Provided | M25: Returns {verification, expiresAt}.
A26: EP-P06 | B26: NITDA Document Portal | C26: STATUS | D26: POST JSON | E26: {referenceId, email} or {referenceId, verification} | F26: core.js:504 | G26: CG_Portal_Status_Check_Endpoint | H26: CG_Portal_Status_Check_Endpoint | I26: npm run keyimpl: implemented | J26: Provided | M26: Returns {record}; 404 or 400 denied; 403 verification_required; 429.
A27: EP-P07 | B27: NITDA Document Portal | C27: WRITEBACK | D27: POST JSON | E27: {referenceId, verification, action, body}; action is respond, note or withdraw | F27: core.js:455 | G27: CG_Portal_Writeback_Endpoint | H27: CG_Portal_Writeback_Endpoint | I27: npm run keyimpl: implemented | J27: Provided | M27: Needs VERIFY and VERIFY_CONFIRM for the proof. Not queued on failure.
A28: EP-M01 | B28: DGO Correspondence Mailer | C28: MAIL_SEND | D28: POST JSON | E28: send | F28: mailer/js/sender.js:187, 290 | G28: Not observed live | H28: DGO_MAIL_SEND | I28: mailer/flows/definitions (dgo-mail/2.0) | J28: Provided with caveat | L28: A-20 | M28: Allowlist gov.ng and edu.ng, at most 10 recipients, about 21 MB of attachments.
A29: EP-M02 | B29: DGO Correspondence Mailer | C29: MAIL_LOG | D29: POST JSON | E29: list, get | F29: sender.js:263; views/sent.js:173; views/outbox.js:87 | G29: Not observed live | H29: DGO_MAIL_LOG | I29: As EP-M01 | J29: Provided with caveat | L29: A-20
A30: EP-M03 | B30: DGO Correspondence Mailer | C30: MAIL_DIRECTORY | D30: POST JSON | E30: list, upsert, delete | F30: views/directory.js; sync.js:173 | G30: Not observed live | H30: DGO_MAIL_DIRECTORY | I30: As EP-M01 | J30: Provided with caveat | L30: A-20
A31: EP-M04 | B31: DGO Correspondence Mailer | C31: MAIL_TEMPLATES | D31: POST JSON | E31: list, upsert, delete | F31: views/templates.js; sync.js:199 | G31: Not observed live | H31: DGO_MAIL_TEMPLATES | I31: As EP-M01 | J31: Provided with caveat | L31: A-20
A32: EP-M05 | B32: DGO Correspondence Mailer | C32: MAIL_PROVISION | D32: POST JSON | E32: provision | F32: Setup and Settings | G32: Not observed live | H32: DGO_MAIL_PROVISION | I32: As EP-M01 | J32: Provided with caveat | L32: A-20 | M32: Creates the mailer lists and file library.
A33: EP-M06 | B33: DGO Correspondence Mailer | C33: MAIL_AUTH | D33: POST JSON | E33: requestCode, verifyCode, whoAmI, signOut, listOperators, upsertOperator | F33: mailer/js/session.js:42-61; views/settings.js:173 | G33: Not observed live | H33: DGO_MAIL_AUTH | I33: As EP-M01 | J33: Provided with caveat | L33: A-19, A-20 | M33: Missing from the committed config template. With it unset the app skips sign-in.
A34: EP-M07 | B34: DGO Correspondence Mailer | C34: MAIL_DATA | D34: POST JSON | E34: mailings, reports and files operations | F34: mailer/js/sync.js | G34: Not observed live | H34: DGO_MAIL_DATA | I34: As EP-M01 | J34: Provided with caveat | L34: A-19, A-20 | M34: Missing from the committed config template.
A35: EP-T01 | B35: Folio Flow Workbench | C35: GET /api/health | D35: GET | E35: none | F35: tools/flow-workbench/app.js:121 | G35: n/a | H35: n/a | I35: tools/flow-workbench/local_agent.py | J35: Provided | M35: Local relay on 127.0.0.1:8765.
A36: EP-T02 | B36: Folio Flow Workbench | C36: POST /api/request | D36: POST JSON | E36: {url, method, headers, body, timeoutSeconds} | F36: app.js:519 | G36: n/a | H36: n/a | I36: local_agent.py | J36: Provided | M36: Relays to HTTPS targets only; browser origin locked to the relay.
A37: EP-T03 | B37: Folio Flow Workbench | C37: Direct flow URL | D37: Browser fetch | E37: any method | F37: app.js:531 | G37: n/a | H37: n/a | I37: app.js | J37: Provided | M37: Reply is unreadable because flows send no CORS headers.
A38: EP-T04 | B38: Folio Vault | C38: GET /health | D38: GET | E38: none | F38: Readiness probe | G38: n/a | H38: n/a | I38: tools/flow-capsule/app/flowcapsule.py | J38: Provided | M38: No token needed.
A39: EP-T05 | B39: Folio Vault | C39: /admin/flows routes (8) | D39: GET, POST | E39: list, register, versions, verify, rollback, enable, disable | F39: core/capsule-client.js from Admin Suite | G39: n/a | H39: n/a | I39: flowcapsule.py | J39: Provided | M39: Bearer token required. Optional platform.
A40: EP-T06 | B40: Folio Estate Console and Admin Suite | C40: Configured flow URLs | D40: Browser fetch | E40: healthCheck, verify, manual invoke | F40: modules/admin-suite.js:1558; tools/admin-console.html:2528 | G40: n/a | H40: n/a | I40: As called | J40: Provided | M40: Uses the Workspace keys; adds none.

Sheet Operations
A1: R3 · Operation register
A2: Operations sent to flows that route on an operation, checked against the flow known list and its cases.
A4: ID | B4: Endpoint key | C4: Operation | D4: Sent by (call site) | E4: In known list | F4: Implemented | G4: Result | H4: Finding | I4: Action
A5: OP-D01 | B5: DYNAMIC_ACTIONS | C5: update (document flag) | D5: core/document-flags.js:146; modules/activities.js; modules/lookup.js:105 | E5: Yes | F5: Yes | G5: Works
A6: OP-D02 | B6: DYNAMIC_ACTIONS | C6: update-task | D6: modules/lookup.js:132 | E6: Yes | F6: Yes | G6: Works
A7: OP-D03 | B7: DYNAMIC_ACTIONS | C7: dispatch | D7: modules/dispatch.js:39, 56 | E7: Yes | F7: No | G7: 501 not implemented | H7: F-02 | I7: A-05
A8: OP-D04 | B8: DYNAMIC_ACTIONS | C8: dispatchOutbound | D8: core/dispatch-service.js:17 | E8: Yes | F8: No | G8: 501 not implemented | H8: F-02 | I8: A-05
A9: OP-D05 | B9: DYNAMIC_ACTIONS | C9: activity-archive, activity-nysc, activity-siwes, each with :create-queue-record, :set-reference-id, :update-activity (12 operations) | D9: modules/activities.js:171; config/dynamic-actions.config.js | E9: Yes | F9: No | G9: 501 not implemented | H9: F-02 | I9: A-05
A10: OP-D06 | B10: DYNAMIC_ACTIONS | C10: user-admin:* | D10: modules/user-admin.js:34 | E10: No | F10: No | G10: 400 unknown operation | H10: F-02 | I10: A-05, A-06
A11: OP-D07 | B11: DYNAMIC_ACTIONS | C11: route | D11: modules/response-tracking.js:39 | E11: No | F11: No | G11: 400 unknown operation | H11: F-02 | I11: A-05, A-06
A12: OP-D08 | B12: DYNAMIC_ACTIONS | C12: upsert_record, transition_status (sent as action, not operation) | D12: modules/meetings.js:157, 202, 232 | E12: No | F12: No | G12: 400 unknown operation | H12: F-02 | I12: A-05, A-06
A13: OP-D09 | B13: DYNAMIC_ACTIONS | C13: read | D13: modules/lookup.js:57; modules/fasttrack.js:33 | E13: No | F13: No | G13: 400 unknown operation | H13: F-02 | I13: A-05, A-06
A14: OP-S01 | B14: SUBSIDIARY_ACTIONS | C14: ACKNOWLEDGE | D14: core/acknowledgement-service.js:171; core/offline-action-queue.js:14 | E14: No | F14: No | G14: 400 unknown operation | H14: F-01 | I14: A-04
A15: OP-S02 | B15: SUBSIDIARY_ACTIONS | C15: CREATESUPPORTREQUEST | D15: core/support-service.js:8 | E15: No | F15: No | G15: 400 unknown operation | H15: F-01 | I15: A-04
A16: OP-S03 | B16: SUBSIDIARY_ACTIONS | C16: read | D16: modules/lookup.js:57; modules/fasttrack.js:33 | E16: No | F16: No | G16: 400 unknown operation | H16: F-01 | I16: A-04
A17: OP-M01 | B17: MAIL_SEND | C17: send | D17: mailer client (see EP-M01 to EP-M07) | E17: Yes | F17: Yes | G17: Defined in the flow; not observed live | I17: A-20
A18: OP-M02 | B18: MAIL_LOG | C18: list | D18: mailer client (see EP-M01 to EP-M07) | E18: Yes | F18: Yes | G18: Defined in the flow; not observed live | I18: A-20
A19: OP-M03 | B19: MAIL_LOG | C19: get | D19: mailer client (see EP-M01 to EP-M07) | E19: Yes | F19: Yes | G19: Defined in the flow; not observed live | I19: A-20
A20: OP-M04 | B20: MAIL_DIRECTORY | C20: list | D20: mailer client (see EP-M01 to EP-M07) | E20: Yes | F20: Yes | G20: Defined in the flow; not observed live | I20: A-20
A21: OP-M05 | B21: MAIL_DIRECTORY | C21: upsert | D21: mailer client (see EP-M01 to EP-M07) | E21: Yes | F21: Yes | G21: Defined in the flow; not observed live | I21: A-20
A22: OP-M06 | B22: MAIL_DIRECTORY | C22: delete | D22: mailer client (see EP-M01 to EP-M07) | E22: Yes | F22: Yes | G22: Defined in the flow; not observed live | I22: A-20
A23: OP-M07 | B23: MAIL_TEMPLATES | C23: list | D23: mailer client (see EP-M01 to EP-M07) | E23: Yes | F23: Yes | G23: Defined in the flow; not observed live | I23: A-20
A24: OP-M08 | B24: MAIL_TEMPLATES | C24: upsert | D24: mailer client (see EP-M01 to EP-M07) | E24: Yes | F24: Yes | G24: Defined in the flow; not observed live | I24: A-20
A25: OP-M09 | B25: MAIL_TEMPLATES | C25: delete | D25: mailer client (see EP-M01 to EP-M07) | E25: Yes | F25: Yes | G25: Defined in the flow; not observed live | I25: A-20
A26: OP-M10 | B26: MAIL_PROVISION | C26: provision | D26: mailer client (see EP-M01 to EP-M07) | E26: Yes | F26: Yes | G26: Defined in the flow; not observed live | I26: A-20
A27: OP-M11 | B27: MAIL_AUTH | C27: requestCode | D27: mailer client (see EP-M01 to EP-M07) | E27: Yes | F27: Yes | G27: Defined in the flow; not observed live | I27: A-20
A28: OP-M12 | B28: MAIL_AUTH | C28: verifyCode | D28: mailer client (see EP-M01 to EP-M07) | E28: Yes | F28: Yes | G28: Defined in the flow; not observed live | I28: A-20
... A42: OP-M26 | B42: MAIL_DATA | C42: deleteFile | D42: mailer client (see EP-M01 to EP-M07) | E42: Yes | F42: Yes | G42: Defined in the flow; not observed live | I42: A-20
A43: OP-M27 | B43: All seven mailer keys | C43: healthCheck, verify | D43: mailer/js/api.js; Settings | E43: Yes | F43: Yes | G43: Defined in every mailer flow
A44: OP-P01 | B44: WRITEBACK | C44: respond | D44: document-portal/js/core.js:455 | E44: Yes | F44: Yes | G44: Works
A45: OP-P02 | B45: WRITEBACK | C45: note | D45: core.js:455 | E45: Yes | F45: Yes | G45: Works
A46: OP-P03 | B46: WRITEBACK | C46: withdraw (the only one that changes status) | D46: core.js:455 | E46: Yes | F46: Yes | G46: Works

Sheet Supporting
A1: R4 · Supporting flows, lists and services
A2: Not endpoints a platform calls. The required flows only work if these are in place.
A4: ID | B4: Item | C4: Kind | D4: What depends on it | E4: What the branch shows | F4: Status | G4: Finding | H4: Action
A5: SUP-01 | B5: AUTO_SCHEDULED_SWEEP | C5: Scheduled flow (recurrence trigger, no URL) | D5: The eight timed notifications: citizen reminders, escalations, owner alerts and an operations alert (matrix rows RN-002, 003, 004, 008, 013, 014, 026, 027). | E5: Deployed (readiness ITEM-49). List-threshold failure closed (ITEM-45). Seven of eight mail actions go to a composed recipient; one alerts a fixed address about undelivered notifications. | F5: Provided
A6: SUP-02 | B6: DGO_USERDIRECTORY_SYNC | C6: Sync flow, Microsoft 365 to DGO_UserDirectory | D6: Every gated internal flow looks up the caller and role in DGO_UserDirectory. The Workspace users collection comes from the same list. | E6: Package built and run through six simulated scenarios. Never overwrites Role, Persona, AccessScope or PilotCohort. No export or tenant reading shows it deployed. | F6: Not examined | H6: A-15
A7: SUP-03 | B7: Flow Configuration list (allowed origins) | C7: SharePoint list on NITDADGO-EAAACTIVITYTRACKING | D7: Every portal, internal and mailer flow reads it to answer CORS. It must list https://internal-platform.rf.gd (Workspace and mailer) and https://activityweb.page.gd (portal). | E7: Portal flows reading a list on the internal site is an accepted exception (D16). The OTP allow-list row was applied by the operator and not verified (ITEM-56). | F7: Provided with caveat | H7: A-16
A8: SUP-04 | B8: SharePoint lists and libraries | C8: Provisioning prerequisite | D8: Rate limits, OTP records, upload tickets, sequence counters, verification proofs, telemetry, audit. Ten governance lists, twelve portal lists, and the mailer eight lists and file library. | E8: Governance lists verified present on 9 Sep (97 present, 10 seeds). Portal lists from 07-portal-provisioning.flow.json. Mailer lists from DGO_MAIL_PROVISION. Portal Flow Telemetry.RunRecordJson applied but unverified (ITEM-30). | F8: Provided with caveat | H8: A-20
A9: SUP-05 | B9: ECM_DOCS_INTAKE | C9: Bridge flow (HTTP, tenant-authenticated) | D9: The design one portal-to-internal crossing: reads the portal registry for the internal platform and writes status back (D1). The Workspace public-portal channel is meant to arrive through FETCH_ALL. | E9: The flow exists. No Workspace code and no exported flow calls it, and the FETCH_ALL package reads no portal list. | F9: Gap | H9: A-14
A10: SUP-06 | B10: Internal proof ledger | C10: SharePoint list | D10: The internal OTP-verify and FETCH_ALL kits mint and read internal-session proofs from it. | E10: Decided as a separate list and not yet provisioned (ITEM-64). The live packages do not carry the check. | F10: Not examined | H10: A-17
A11: SUP-07 | B11: Outlook mailboxes | C11: Microsoft 365 connection | D11: Every flow with a send action. Service mailbox dgsregistry@nitda.gov.ng; the mailer sends as its connection or a shared mailbox. | E11: Sending identity is marked TENANT_VERIFICATION_REQUIRED in config/notification-delivery.config.js. | F11: Not examined | H11: A-18
A12: SUP-08 | B12: Power Automate Management connector | C12: Connector | D12: GetFlow in the flows that write run records: EMAIL_RELATED_TASK, FETCH_ALL (11 Sep), FETCH_EMAIL_ATTACHMENTS, VERIFY_CONFIRM, WRITEBACK. | E12: The connection must be bound in the tenant. | F12: Not examined | H12: A-18
A13: SUP-09 | B13: Adobe PDF Tools connector and OpenRouter | C13: External services | D13: The AI flow extracts PDF text with Adobe PDF Tools and prompts OpenRouter. | E13: Only the export held calls them. It embeds an API key (F-05). | F13: Gap | G13: F-05 | H13: A-01, A-08
A14: SUP-10 | B14: Web hosts for the static platforms | C14: Hosting | D14: Workspace and mailer at https://internal-platform.rf.gd; portal at https://activityweb.page.gd (sitemap and robots). | E14: Hosts must match the allowed-origins rows in SUP-03 and the mailer allowedOrigin. | F14: Provided with caveat | H14: A-16

Sheet Mail
A1: R5 · Mail obligations register
A2: The 39 required notifications from config/notification-matrix.config.js, with the matrix own status, owner and remediation.
A4: ID | B4: Event | C4: Platform | D4: Audience | E4: Channel | F4: Carrier | G4: Status (matrix) | H4: Severity | I4: Owner | J4: Remediation
A5: RN-001 | B5: A submission is accepted and a reference is minted | C5: portal | D5: citizen | E5: email | F5: docs/deployment/sharepoint/flows/designer-paste/Portal_SUBMISSION_ECM_DOCS.designer-paste.json | G5: ABSENT | H5: Critical | I5: Platform technical owner | J5: Add a Send_Submission_Confirmation action and a Create_Submission_Outbox_Receipt catch to the SUBMISSION package, addressed to the senderEmail already written to Portal Registry.
A6: RN-002 | B6: A record moves to action-required | C6: portal | D6: citizen | E6: email | F6: docs/deployment/internal/flows/import-package/DGO_SCHEDULED_SWEEP (legacy import package, Recurrence trigger) | G6: PROVISIONED | H6: Critical | I6: Process owner, correspondence lifecycle | J6: Requires PRE-2. Either a scheduled sweep of Portal Registry for rows whose status changed, or a send added to whichever write sets the status.
A7: RN-003 | B7: A decision is issued — the record moves to approved | C7: portal | D7: citizen | E7: email | F7: docs/deployment/internal/flows/import-package/DGO_SCHEDULED_SWEEP (legacy import package, Recurrence trigger) | G7: PROVISIONED | H7: Critical | I7: Process owner, correspondence lifecycle | J7: Requires PRE-2. Same carrier as RN-002, keyed on the approved status.
A8: RN-004 | B8: A decision is issued — the record moves to declined | C8: portal | D8: citizen | E8: email | F8: docs/deployment/internal/flows/import-package/DGO_SCHEDULED_SWEEP (legacy import package, Recurrence trigger) | G8: PROVISIONED | H8: Critical | I8: Process owner, correspondence lifecycle | J8: Requires PRE-2. Same carrier as RN-002, keyed on the declined status.
A9: RN-005 | B9: A submitter withdraws their own submission | C9: portal | D9: citizen | E9: email | F9: docs/deployment/sharepoint/flows/designer-paste/Portal_WRITEBACK_ECM_DOCS.designer-paste.json | G9: ABSENT | H9: High | I9: Process owner, correspondence lifecycle | J9: Add a send plus outbox receipt to the withdraw branch of the WRITEBACK package.
A10: RN-006 | B10: A citizen requests a verification code | C10: portal | D10: citizen | E10: email | F10: Portal_VERIFY_ECM_DOCS and Portal_VERIFY_CONFIRM_ECM_DOCS, action Send_Otp_Email | G10: MISADDRESSED | H10: Critical | I10: Platform technical owner | J10: Session 4 fixes this by pasting the package over 86897b2f. Until it is pasted, a citizen cannot complete verification unless someone forwards the code from a shared mailbox. Subject to PRE-1, the sending mailbox decision.
A11: RN-007 | B11: A support case is opened from the portal | C11: portal | D11: citizen | E11: email | F11: Portal_SUPPORT_ECM_DOCS, action Send_Support_Acknowledgement | G11: PROVISIONED | H11: Medium | I11: Platform technical owner | J11: None. Subject to PRE-1, the sending mailbox decision.
A12: RN-008 | B12: A support case is answered or closed | C12: portal | D12: citizen | E12: email | F12: docs/deployment/internal/flows/import-package/DGO_SCHEDULED_SWEEP (legacy import package, Recurrence trigger) | G12: PROVISIONED | H12: High | I12: Registry helpdesk owner | J12: Requires PRE-2, or a helpdesk action that sends on reply.
A13: RN-009 | B13: A record is assigned to one officer | C13: internal | D13: assignee | E13: email | F13: docs/deployment/internal/flows/designer-paste/DGO_SINGLE_ASSIGNMENT.designer-paste.json | G13: REGRESSION | H13: Critical | I13: Platform technical owner | J13: Port the Compose_Email_To_2 recipient expression from Deployed - Create Task into DGO_SINGLE_ASSIGNMENT before Session 4 pastes it. The cascade already computes the same address through categoryFieldAliases.assignedTo, so no new contract is needed.
A14: RN-010 | B14: Records are assigned in bulk | C14: internal | D14: assignee | E14: email | F14: docs/deployment/internal/flows/designer-paste/DGO_BULK_ASSIGNMENT.designer-paste.json | G14: MISADDRESSED | H14: Critical | I14: Platform technical owner | J14: Re-address the nine existing sends to the resolved assignee, or add the send to the replacement package and retire the deployed flows.
A15: RN-011 | B15: A record is assigned with supporting and copy-to parties | C15: internal | D15: supporting | E15: email | F15: DGO_SINGLE_ASSIGNMENT and DGO_BULK_ASSIGNMENT | G15: ABSENT | H15: Medium | I15: Process owner, correspondence lifecycle | J15: Add a second send, addressed to the resolved supporting and copy-to lists.
... A43: RN-039 | B43: An HTTP flow registry exception is open and assigned to someone | C43: flow-estate | D43: assignee | E43: email | F43: Send_Exception_Email, inside Notify_Each_Exception, in 06 - GOV - Registry Exception | G43: PROVISIONED | H43: Medium | I43: Platform technical owner | J43: None outstanding for the carrier. Two things are: this row needs a tenant result like every other, and the standing copy to the registry mailbox on every exception notice is a choice worth confirming rather than inheriting — it is the same decision SN-006 puts to the governance owner about the same flow.

Sheet Findings
A1: R6 · Findings register
A2: Ordered by severity. Status is for tracking.
A4: ID | B4: Severity | C4: Finding | D4: Detail | E4: Evidence | F4: Affects | G4: Actions | H4: Status
A5: F-05 | B5: Critical | C5: An API key is committed where the secret scan does not look | D5: An OpenRouter bearer token (sk-or-v1-...) is in the Authorization header of the HTTP action inside the AI_Document_Processing export. The export is dated 11 Sep, after the agency confirmed on 8 Sep that all provider keys were rotated (readiness ITEM-7). It is either the new key or one that was missed. Two Google API keys (AIzaSy...) sit in the 4 Aug run record, which predates the rotation. ITEM-7 lists four Google keys as rotated; the branch does not say these two are among them. No key was tested. | E5: docs/reference/flow-exports/AI_Document_Processing_20260911185206.zip (definition.json); docs/reference/foundational/flows/run-records/dgso_incoming_ai_processing_provisioning_report_2026-08-04_1/ (definition_raw.json, standard.html); tests/check-secrets.mjs reads text files only; scan of every tracked zip and xlsx found no other match. | F5: EP-W12, EP-W13, SUP-09 | G5: A-01, A-02, A-03 | H5: Open
A6: F-01 | B6: High | C6: SUBSIDIARY_ACTIONS routes are not implemented by the flow that answers the key | D6: The 27 Sep live reading shows the dynamic-actions flow answering this key. It handles four operations and none of the routes the Workspace sends (ACKNOWLEDGE, CREATESUPPORTREQUEST, read). The flow the owner map names, IP_Subsidiary_Actions_Endpoint, does telemetry, CORS and a response only. | E6: docs/deployment/internal/evidence/2026-09-27-live-endpoint-wiring.json; readiness ITEM-65 (blocked); docs/reference/flow-exports/IP_Subsidiary_Actions_Endpoint_20260905193834.zip | F6: EP-W05, OP-S01 to OP-S03 | G6: A-04 | H6: Open
A7: F-02 | B7: High | C7: DYNAMIC_ACTIONS implements 4 of 19 operations, and the Workspace sends others outside the list | D7: dispatch, dispatchOutbound and 12 activity-lifecycle operations answer 501. user-admin:*, route, upsert_record, transition_status and read answer 400 unknown operation. The live flow is the intended IP_Dynamic_Global_Actions_Endpoint (repointed 27 Sep). transitionstatus, logauditevent and archivereference are in the list but the Workspace never calls them. | E7: IP_Dynamic_Global_Actions_Endpoint packages of 12 and 17 Sep (Switch_Dynamic_Operation, Compose_Dynamic_Known_Operations); notification-matrix RN-022 | F7: EP-W06, OP-D03 to OP-D09 | G7: A-05, A-06 | H7: Open
A8: F-03 | B8: High | C8: BULK_ASSIGNMENT is answered by a retrieval flow | D8: The 27 Sep live reading confirms BULK OPS DATA RETRIEVAL HTTP answers this key. Its export reads a document by taskId or runs an OData query and has no assignment write. The owner map names IP_Bulk_Assignment_Endpoint, which does assign. | E8: 2026-09-27-live-endpoint-wiring.json; BULKOPSDATARETRIEVALHTTP_20260911185143.zip; matched bundle IP_Bulk_Assignment_Endpoint_20260901023331.zip | F8: EP-W10 | G8: A-07 | H8: Open
A9: F-04 | B9: High | C9: The AI keys share one flow, and the only export held cannot serve both callers | D9: AI_Document_Processing reads triggerBody()[text_1], fetches a SharePoint item attachments, extracts PDF text through Adobe PDF Tools and posts a prompt to OpenRouter. It has no switch, no directory gate and does not read action, messages, operation or referenceId. The Workspace sends {messages, scoped, context} for AI_CHAT and {operation: classify, referenceId, subject, ...} for AI_DOC_ANALYSIS. The export has a different flow id from the live flow (fefa43c6), whose definition is not in the branch. | E9: AI_Document_Processing_20260911185206.zip; modules/assistant.js:48; modules/correspondence.js:128 | F9: EP-W12, EP-W13 | G9: A-08 | H9: Open
A10: F-11 | B10: High | C10: Three required flows have no caller check | D10: The intended packages for FETCH_EMAIL_ATTACHMENTS, EMAIL_RELATED_TASK and SUBSIDIARY_ACTIONS do not look the caller up in the user directory. Triggers accept anonymous callers and Workspace authentication is disabled, so the flow is the only place a check can happen. FETCH_EMAIL_ATTACHMENTS reads Outlook messages and attachments. EMAIL_RELATED_TASK creates tasks and sends mail. | E10: IP_Retrieve_Email_Attachment_Endpoint_20260906045907, IP_Create_Email_Assignment_Endpoint_20260906043757 and IP_Subsidiary_Actions_Endpoint_20260905193834 packages (no directory list read); docs/deployment/internal/INTERNAL_FLOWS_README.md (caller gate pattern) | F10: EP-W05, EP-W08, EP-W11 | G10: A-22 | H10: Open
A11: F-07 | B11: Medium | C11: Assignment mail: the intended single-assignment flow sends none, and email-to-task sends to one fixed person | D11: The live SINGLE_ASSIGNMENT flow is the older Single_Task_Assignment, which has no export in the branch. The intended package has no send action (matrix RN-009 regression). EMAIL_RELATED_TASK has six send actions all addressed to one named address. | E11: IP_Single_Assignment_Endpoint.READY package; IP_Create_Email_Assignment packages of 6 and 11 Sep; notification-matrix RN-009, RN-010 | F11: EP-W09, EP-W11 | G11: A-10 | H11: Open
A12: F-08 | B12: Medium | C12: FETCH_ALL feeds no emails or approvals and caps every list | D12: Every FETCH_ALL package hard-codes emails and approvals as empty arrays. Each list read is capped at 500 rows (200 for departments). The Workspace email collection has no source in the exported flow. | E12: IP_FETCH_ALL_BOOTSTRAP 17 and 24 Sep; IP_FETCH_ALL__EXTENDED 11 Sep (Set_variable_varData_FetchAll_Success) | F12: EP-W01 | G12: A-11 | H12: Open
A13: F-06 | B13: Low | C13: EMAIL: the live flow is the payload-addressed sender and the notification matrix is out of date | D13: The 27 Sep live reading has IP_SEND_EMAIL answering EMAIL, as the owner intended. Its package composes recipients from the payload, checks the caller and writes a receipt per send. Matrix rows RN-021 and RN-024 still read MISADDRESSED and describe the older Web - Send Email flow; their evidence is dated 2 Sep. The 5 Sep package was read, not the live definition. | E13: 2026-09-27-live-endpoint-wiring.json; IP_SEND_EMAIL_20260905184716.zip; config/notification-matrix.config.js | F13: EP-W07 | G13: A-09 | H13: Open
A14: F-09 | B14: Low | C14: OTP wiring differs between the live reading and the owner map | D14: The live reading has IP_OTP_VERIFY answering both OTP keys. The owner map wants IP_OTP_Endpoint for generate and that repoint is pending. Both exports handle what the Workspace sends. | E14: 2026-09-27-live-endpoint-wiring.json (planOfSameDay); IP_OTP_VERIFY and IP_OTP_Endpoint packages of 5 Sep | F14: EP-W14 | G14: A-12 | H14: Open
A15: F-10 | B15: Low | C15: Flow identity is only partly established | D15: The branch holds a live reading of 27 Sep (693 flows visible). It names the flow behind each of 25 keys: 15 as the owner intended, 9 different, 1 with no row in the owner map. It records no signatures. Exports are matched to keys by flow name, not by id, and the crosswalk records verified: 0. | E15: 2026-09-27-live-endpoint-wiring.json; docs/reference/flow-identity-crosswalk.json | F15: All endpoints | G15: A-13 | H15: Open
A16: F-12 | B16: Low | C16: The mailer package documents its configuration inconsistently | D16: mailer/config.js and mailer/config.local.example.js list 5 of the 7 keys the app requires (MAIL_AUTH and MAIL_DATA are missing). scripts/platforms.config.mjs says five flows. docs/reference/PLATFORM_NAMING.md says five platforms and omits the mailer. The mailer flows and lists are recorded as specified, not observed. | E16: mailer/js/settings.js (ENDPOINT_KEYS, isDeployed); mailer/js/app.js:76; docs/reference/ESTATE-REGISTER.md | F16: EP-M06, EP-M07 | G16: A-19, A-20 | H16: Open

Sheet Actions
A1: R7 · Action register
A2: Proposed actions. Owners are the roles the branch itself names. Fill in the yellow tracking columns.
A4: ID | B4: Priority | C4: Action | D4: Type | E4: Owner (role) | F4: Acceptance test | G4: Depends on | H4: Register refs | I4: Findings | J4: Status | K4: Assigned to | L4: Target date
A5: A-01 | B5: P1 | C5: Revoke the OpenRouter key embedded in the AI_Document_Processing export, take the key out of the flow definition (use a connection or secret), and record the revocation with the provider. | D5: Security | E5: Platform technical owner with the agency | F5: The provider shows the old key revoked. A fresh export of the flow contains no sk-or- string. A scan of the repository including zip files finds none. | H5: ITEM-7 | I5: F-05 | J5: Proposed
A6: A-02 | B6: P1 | C6: Confirm the two Google keys in the 4 Aug run record are among the four rotated Google keys. If not, revoke them. | D6: Security | E6: Agency | F6: Provider console shows both keys revoked or deleted. | H6: ITEM-7 | I6: F-05 | J6: Proposed
A7: A-03 | B7: P2 | C7: Extend tests/check-secrets.mjs to open zip and xlsx files and scan for provider-key patterns (sk-or-v1-, AIza, hf_). | D7: Control | E7: Platform technical owner | F7: The test fails on the current AI export until A-01 is done, then passes. | G7: A-01 | I7: F-05 | J7: Proposed
A8: A-04 | B8: P1 | C8: Implement the SUBSIDIARY_ACTIONS routes ACKNOWLEDGE, CREATESUPPORTREQUEST and read. Either add a switch to IP_Subsidiary_Actions_Endpoint and repoint the key to it, or add the cases to the dynamic-actions flow and its known list. | D8: Build | E8: Flow builder (platform owner decides the route) | F8: A POST with each operation returns 200 with the write applied. A live reading shows the key as intended. ITEM-65 closes. | H8: ITEM-65 | I8: F-01 | J8: Proposed
A9: A-05 | B9: P1 | C9: Add cases for the operations the Workspace sends to DYNAMIC_ACTIONS: dispatch, dispatchOutbound (ITEM-25), the 12 activity-lifecycle operations, user-admin:*, route, upsert_record, transition_status and read. Add each to the known list. | D9: Build | E9: Flow builder | F9: npm run test:dynamicops passes with the extended set. Each operation returns something other than 501 or 400 against the live flow. | G9: A-06 | H9: ITEM-25 | I9: F-02 | J9: Proposed
A10: A-06 | B10: P2 | C10: Align the client with the flow contract: make meetings send operation instead of action, and settle the names used by user-admin and response-tracking so every sent operation is in the known list. | D10: Build | E10: Platform technical owner | F10: Every operation in the operation register OP-D01 to OP-D09 is in the flow known list. npm run test:dynamicops passes. | I10: F-02 | J10: Proposed
A11: A-07 | B11: P1 | C11: Repoint BULK_ASSIGNMENT to IP_Bulk_Assignment_Endpoint, or let that flow take over the workflow id. Retire the retrieval binding. | D11: Wiring | E11: Platform owner (decision) and operator (repoint) | F11: A live reading shows the key as intended. A bulk assignment test updates every selected task and writes an audit row. | H11: ITEM-65 | I11: F-03 | J11: Proposed
A12: A-08 | B12: P1 | C12: Bring the live AI_Document_Processing definition (flow id fefa43c6) into the branch. Add a router on action for aiChat and aiAnalyseEventDocs, a directory gate, and inputs for messages, context and referenceId. Keep credentials in a connection. | D12: Build | E12: Flow builder | F12: Both AI calls from the Workspace return an answer. The definition in the branch matches the live flow id. | G12: A-01 | I12: F-04 | J12: Proposed
A13: A-09 | B13: P3 | C13: Read the live IP_SEND_EMAIL definition and update matrix rows RN-021 and RN-024, then re-run scripts/verify-notification-matrix.mjs. | D13: Records | E13: Platform technical owner | F13: The matrix status matches the live definition and the verifier passes. | I13: F-06 | J13: Proposed
A14: A-10 | B14: P2 | C14: Add assignee notification to the intended single-assignment package (port the recipient expression from Deployed - Create Task, matrix RN-009), repoint SINGLE_ASSIGNMENT, and re-address the six fixed sends in EMAIL_RELATED_TASK to the resolved assignee. | D14: Build | E14: Flow builder | F14: An assignment sends one mail to the assignee and none to a fixed address. Matrix RN-009 and RN-010 change status. | H14: RN-009, RN-010 | I14: F-07 | J14: Proposed
A15: A-11 | B15: P2 | C15: Feed emails and approvals from FETCH_ALL, or remove those collections from the Workspace. Add paging beyond 500 rows (200 for departments). | D15: Build | E15: Flow builder with the platform owner | F15: A test mailbox with mail returns a non-empty emails collection. A list of more than 500 rows returns all rows. | I15: F-08 | J15: Proposed
A16: A-12 | B16: P3 | C16: Finish the OTP_GENERATE repoint to IP_OTP_Endpoint once its package is fixed, or amend the owner map to accept IP_OTP_VERIFY for both keys. | D16: Wiring | E16: Platform owner | F16: Live reading and owner map agree for OTP_GENERATE. | I16: F-09 | J16: Proposed
A17: A-13 | B17: P3 | C17: Extend the live reading to record each flow definition and id, so exports match keys by id, and record verified in the crosswalk. | D17: Records | E17: Platform technical owner | F17: flow-identity-crosswalk.json shows verified greater than 0 and no key matched by name only. | H17: ITEM-65 | I17: F-10 | J17: Proposed
A18: A-14 | B18: P2 | C18: Decide and document how portal submissions reach the Workspace: read the portal registry through the tenant-authenticated ECM_DOCS_INTAKE bridge from FETCH_ALL, or accept a portal-only path. | D18: Decision | E18: Agency (decisions D1 and D6, ITEM-37) | F18: A written decision. If the bridge is used, a submission made in the portal appears in the Workspace with the public-portal channel. | H18: ITEM-37 | I18: SUP-05 | J18: Proposed
A19: A-15 | B19: P2 | C19: Deploy DGO_USERDIRECTORY_SYNC into a recurrence flow and record a tenant reading of it. | D19: Deploy | E19: Platform technical owner with the tenant administrator | F19: DGO_UserDirectory rows update from Microsoft 365, an audit row is written per run, and the flow appears in a live reading. | I19: SUP-02 | J19: Proposed
A20: A-16 | B20: P2 | C20: Verify the allowed-origins rows for https://internal-platform.rf.gd and https://activityweb.page.gd against the CORS answer of every flow, including the mailer allowedOrigin. | D20: Verify | E20: Operator | F20: A browser call from each host to each flow succeeds and reads the reply. | H20: ITEM-56 | I20: SUP-03, SUP-10 | J20: Proposed
A21: A-17 | B21: P3 | C21: Provision the internal proof ledger list before pasting the DGO_FETCH_ALL and DGO_OTP_VERIFY kits. | D21: Provision | E21: Operator | F21: The list exists with Purpose and Consumed columns. npm run test:proofidentity passes. | H21: ITEM-64 | I21: SUP-06 | J21: Proposed
A22: A-18 | B22: P2 | C22: Verify the Outlook sending identity and shared mailbox, and bind the Power Automate Management connection, in the tenant. | D22: Verify | E22: Tenant administrator | F22: A test send from each mail-sending flow arrives from the intended address. GetFlow succeeds in the run-record flows. | H22: PRE-1 | I22: SUP-07, SUP-08 | J22: Proposed
A23: A-19 | B23: P3 | C23: Fix the mailer documentation: add MAIL_AUTH and MAIL_DATA to config.js and config.local.example.js, change the platforms.config summary to seven flows, and update PLATFORM_NAMING.md to six platforms. | D23: Records | E23: Platform technical owner | F23: Filling the committed template makes isDeployed true. The documents agree on seven flows and six platforms. | I23: F-12 | J23: Proposed
A24: A-20 | B24: P2 | C24: Run the mailer setup in the tenant and record a reading of its seven flows and lists. | D24: Verify | E24: Operator | F24: ESTATE-REGISTER shows the mailer flows and lists as observed. Each of the 26 mailer operations answers a healthCheck. | G24: A-19 | I24: F-12 | J24: Proposed
A25: A-21 | B25: P2 | C25: Work the mail obligations still open in the notification matrix: 9 absent, 6 misaddressed, 2 regression, 2 unimplemented, 4 local-only. Use each row remediation. | D25: Build | E25: Owners named per row in the matrix | F25: Matrix statuses move to PROVISIONED as verified by scripts/verify-notification-matrix.mjs. | G25: A-09, A-10 | H25: RN rows | I25: MAIL register | J25: Proposed
A26: A-22 | B26: P2 | C26: Add the directory caller gate (Status active plus role permission) to FETCH_EMAIL_ATTACHMENTS, EMAIL_RELATED_TASK and the SUBSIDIARY_ACTIONS flow. | D26: Build | E26: Flow builder | F26: A call with an unknown email returns 401 and with a role lacking permission returns 403, and no mail or task is touched. | G26: A-04 | I26: F-11 | J26: Proposed

Sheet Excluded
A1: R8 · Declared but not required
A2: Present in the branch, with no call site in a platform and no required flow depending on them.
A4: ID | B4: Item | C4: Reason
A5: EX-01 | B5: AI_EMAIL_ANALYSIS | C5: Contract, settings label and workflow binding exist. No caller.
A6: EX-02 | B6: BULK_ASSIGNMENT_DIRECT | C6: Contract, settings label and adapter entry exist. No caller.
A7: EX-03 | B7: SUBSIDIARY_ACTIONS route keys | C7: REFRESH_EMAILS, LOAD_EMAIL_DETAILS, AI_ANALYSE_EMAIL, CREATE_TASK, UPDATE_TASK, LOAD_EVENT_INFO, AI_CHAT, TRACK, GET_ALL, GET_BOOTSTRAP, LISTDOCS, GETDOC, BULKASSIGN, GETREFERENCES. Declared, never sent.
A8: EX-04 | B8: Unused aliases | C8: VERIFY_OTP_AND_EXECUTE, TRANSITION_STATUS, LOG_AUDIT_EVENT, ARCHIVE_REFERENCE. The client calls none of them.
A9: EX-05 | B9: Vault invoke route | C9: POST /invoke/{alias}. The client omits it on purpose.
A10: EX-06 | B10: Governance flows and unbound exports | C10: The GOV - flows and every exported flow that is neither bound to a key nor listed in the supporting register. No platform code calls them and no required flow depends on them.
A11: EX-07 | B11: Register workflow records | C11: The 51 workflow records other than the 20 bound to keys.
A12: EX-08 | B12: Estate tooling | C12: Scripts using the Power Automate Management API and Microsoft sign-in, and the mailer setup tool. They provision and commission once; no platform calls them at run time.

Sheet Sources
A1: R9 · Sources and evidence
A2: What was read to build the registers.
A4: ID | B4: Source | C4: Used for
A5: S-01 | B5: docs/reference/endpoint-register.json and config/endpoint-atlas.data.js | C5: Register: workflow bound to each of 25 keys
A6: S-02 | B6: docs/reference/contract-key-flow-map.json and contract-key-flow-reconciliation.json | C6: Owner map (24 Sep): intended flow per key; reconciliation of 24 keys
A7: S-03 | B7: docs/deployment/internal/evidence/2026-09-27-live-endpoint-wiring.json | C7: Live reading (27 Sep): flow answering each key; 693 flows visible
A8: S-04 | B8: docs/deployment/PRODUCTION_READINESS_REGISTER.json | C8: Register items ITEM-7, 25, 30, 37, 45, 49, 56, 59, 64, 65
A9: S-05 | B9: config/notification-matrix.config.js | C9: 39 required notifications and their status
A10: S-06 | B10: docs/reference/flow-exports/*.zip (12 packages) | C10: Flow definitions parsed for triggers, cases, connectors, lists, mail, HTTP hosts
A11: S-07 | B11: artifacts/matched-flow-packages/2026-09-24/Matched_Flow_ZIP_Packages_Available.zip | C11: 20 packages matched to contract keys
A12: S-08 | B12: mailer/flows/flows.catalogue.json, mailer/flows/packages, mailer/js | C12: Mailer contract dgo-mail/2.0, seven flows and client call sites
A13: S-09 | B13: docs/deployment/sharepoint/portal-wiring.json | C13: Portal trust boundary, bridge and accepted crossings
A14: S-10 | B14: docs/reference/flow-identity-crosswalk.json | C14: Key to tenant-flow candidates; verified count
A15: S-11 | B15: core/, modules/, shared/, document-portal/js, mailer/js, tools/ | C15: Call sites in platform code
... A17: S-13 | B17: npm run keyimpl; npm run platforms; tests/check-secrets.mjs | C17: Commands run at this baseline
